Workbook
Name _Order1: 255
Name _Regression_Int: 1
Name \a: #N/A
Name Countries: [1]List!$A$1:$A$31
Name CUAD.0: #N/A
Name CUAD.0CONT: #N/A
Name CUAD.1: #N/A
Name CUAD.1CONT: #N/A
Name CUAD.2: #N/A
Name CUAD.2CONT: #N/A
Name fech_cambi: #REF!
Name fech_cambi: #REF!
Name fech_cambi: #REF!
Name fech_cambi: #REF!
Name fech_cambi: #REF!
Name fech_cambi: #REF!
Name fech_cambi: #REF!
Name gv: #REF!
Name gv: #REF!
Name gv: #REF!
Name gv: #REF!
Name gv: #REF!
Name gv: #REF!
Name gv: #REF!
Name ip: #REF!
Name ip: #REF!
Name ip: #REF!
Name ip: #REF!
Name ip: #REF!
Name ip: #REF!
Name ip: #REF!
Name iq: #REF!
Name iq: #REF!
Name iq: #REF!
Name iq: #REF!
Name iq: #REF!
Name iq: #REF!
Name iq: #REF!
Name PPP_: '[2]10. Mobility Matrices'!$N$60
Name PPP_: '[3]10. Mobility Matrices'!$N$60
Name PPP_: '[4]10. Mobility Matrices'!$N$60
Name Títulos_a_imprimir_IM: '[5]SAN LUIS'!$A$102:$IV$107,'[5]SAN LUIS'!$A$1:$A$65536
Name Títulos_a_imprimir_IM: '[6]SAN LUIS'!$A$102:$IV$107,'[6]SAN LUIS'!$A$1:$A$65536
Name Variables: [1]List!$B$1:$B$45

Sheet Title
B10: CEQ DATA CENTER ON FISCAL REDISTRIBUTION
B11: CEQ Standard indicators web version 4.0
B12: May 15, 2020
B14: The Commitment to Equity (CEQ) Institute works to reduce inequality and poverty through comprehensive and rigorous tax and benefit incidence analysis, and active engagement with the policy community. Building on the seven years of achievements of the CEQ project, the Institute was founded in May 2015 with Nora Lustig as its Director. The CEQ Data Center on Fiscal Redistribution consists of an information and monitoring system with key indicators and a harmonized micro-fiscal database to assess the impact of fiscal systems on inequality and poverty. Among the key questions that the Data Center will allow users to address are: (i) What is the impact of taxes and transfers on inequality and poverty? (ii) How progressive is public spending on education and health? (iii) What is the contribution of specific taxes and transfers to the overall impact? (iv) How effective is the fiscal system in reducing inequality and poverty? (v) How much additional fiscal and redistributive effort is required to end extreme poverty and equalize opportunities? (vi) What is the impact of fiscal policy reforms on inequality and the poverty? The application of the common analytical framework described in the CEQ Handbook (Lustig, editor, 2018) allows for cross-country comparison and benchmarking, both of which can be influential in the context of in-country policy dialogue. http://www.commitmentoequity.org/publications-ceq-handbook/ The indicators presented here are for the United States and 46 low and middle income countries in the CEQ Data Center: Albania, Argentina, Armenia, Bolivia, Belarus, Brazil, Burkina Faso, Chile, Colombia, Comoros, Costa Rica, Croatia, Dominican Republic, Ecuador, Egypt, El Salvador, Ethiopia, Georgia, Ghana, Guatemala, Guinea, Honduras, Indonesia, Iran, Jordan, Kenya, Mali, Mexico, Mongolia, Namibia, Nicaragua, Niger, Panama, Paraguay, Peru, Poland, Romania, Russia, South Africa,Spain, Sri Lanka, Tanzania, Tunisia, Uganda, Ukraine, United States, Uruguay and Venezuela. The CEQ Data Center has been made possible thanks to the generous support of the Bill & Melinda Gates Foundation.
B16: For all Data Center inquiries and data requests: datacenter@ceqinstitute.org

Sheet Contents
C2: Contents
B3: 1 | C3: CEQ methodology
B4: 2 | C4: CEQ Core income concepts
B5: 3 | C5: General information
B6: 4 | C6: Taxes and transfers as a share of GDP
B7: 5 | C7: Inequality gini coefficient
B8: 6 | C8: Inequality Theil Index
B9: 7 | C9: Inequality 90/10 ratio
B10: 8 | C10: Inequality Absolute Gini
B11: 9 | C11: Poverty headcount ratio 2005PPP
B12: 10 | C12: Poverty headcount ratio 2011PPP
B13: 11 | C13: Poverty gap and squared poverty gap PDI 2005PPP
B14: 12 | C14: Poverty gap and squared poverty gap PDI 2011PPP
... B29: 27 | C29: Household surveys

Sheet 1. CEQ Methodology
A1: Go to Contents
B8: CEQ Methodology
B10: Lustig, Nora, editor. 2018. Commitment to Equity Handbook. Estimating the Impact of Fiscal Policy on Inequality and Poverty (Brookings Institution Press and CEQ Institute, Tulane University).
B11: Online version available by clicking here.
B13: The Commitment to Equity Handbook. Estimating the Impact of Fiscal Policy on Inequality and Poverty is a unique manual with a step-by-step guide to apply fiscal incidence analysis as well as country studies to illustrate the impact. The handbook is open access under a CC-BY-NC-ND 4.0 International Public License thanks to the generous support of the Bill & Melinda Gates Foundation.

Sheet 2. CEQ Core income concepts 
A1: Go to Contents
B5: CEQ Core income concepts
B60: Lustig, Nora, editor. 2018. Commitment to Equity Handbook. Estimating the Impact of Fiscal Policy on Inequality and Poverty (Brookings Institution Press and CEQ Institute, Tulane University).

Sheet 3. General information
A1: Go to Contents
B3: General information on the CEQ assessments
B4: NOTE: FOR SOURCES AND CITATIONS SEE BOTTOM OF PAGE
B6: Country | C6: Year of survey | D6: Year of budgetary data and fiscal system | E6: Methodology based on CEQ Handbook *** | F6: Welfare aggregate | I6: Imputed rent calculated for owner's occupied housing | J6: Indirect effects of indirect taxes | K6: Indirect effects of subsidies | L6: Method for health expenditure allocation**** | M6: GNI per capita for fiscal year in 2005ppp | N6: GNI per capita for fiscal year in 2011ppp | O6: Population | P6: GDP (current LCU) | Q6: Household Survey Name
F7: Consumption -or income- based | G7: Variable observed in survey | H7: Consumption of own production
A8: =A7+1 -> 1 | B8: *,** Albania (2015) | C8: 2015 | D8: 2015 | E8: CEQHB 2018 | F8: C | G8: Disposable Income | I8: No | J8: Yes (excise taxes on intermediate goods) | N8: 11800 | O8: 2880703 | P8: 1434307000000 | Q8: Household Budget Survey
A9: =A8+1 -> 2 | B9: Argentina (2012) | C9: 2012-13 | D9: 2012 | E9: CEQHB 2013 | F9: I | G9: Net Market Income | H9: Yes | I9: Yes | J9: Yes | K9: No | L9: Insurance value - Intermediate | M9: 7402.6 | N9: 19130 | O9: 36138213 | P9: 2.6379138e+12 | Q9: Encuesta Nacional de Gasto de los Hogares 2012-2013
A10: =A9+1 -> 3 | B10: Armenia (2011) | C10: 2011 | D10: 2011 | E10: CEQHB 2018 | F10: I | G10: Disposable Income | H10: Yes | I10: Yes | J10: No | K10: No | L10: Actual Use | M10: 2156.7 | N10: 7270 | O10: 2965466.5 | P10: 3777945600000 | Q10: Integrated Living Conditions Survey 2011
A11: =A10+1 -> 4 | B11: *,** Belarus (2015) | C11: 2015 | D11: 2016 | F11: C | G11: Disposable Income | J11: Yes | K11: Yes | N11: 16450.216 | O11: 9489616 | P11: 89909810000 | Q11: Household Budget Survey
A12: =A11+1 -> 5 | B12: Bolivia (2009) | C12: 2009 | D12: 2009 | E12: CEQHB 2011 | F12: I | G12: Net Market Income | H12: No | I12: Yes | J12: No | K12: No | L12: Insurance value - Intermediate | M12: 1130.5 | N12: 4910 | O12: 10232625 | P12: 1.2172675e+11 | Q12: Encuesta de Hogares 2009
A13: =A12+1 -> 6 | B13: Brazil (2008) | C13: 2008-09 | D13: 2009 | E13: CEQHB 2018 | F13: I | G13: Market Income | H13: Yes | I13: Yes | J13: No | K13: No | L13: Insurance value - Access | M13: 4994.1 | N13: 12920 | O13: 1.905193e+08 | P13: 3333039000000 | Q13: Pesquisa de Orçamentos Familiares 2008-2009
A14: =A13+1 -> 7 | B14: *,** Burkina Faso (2014) | C14: 2014 | D14: 2014 | E14: CEQHB 2018 | F14: C | G14: Disposable Income | H14: Yes | I14: Yes | N14: 1620 | O14: 17586017 | P14: 6119568000000 | Q14: Enquête Multisectorielle Continue
A15: =A14+1 -> 8 | B15: Chile (2013) | C15: 2013 | D15: 2013 | E15: CEQHB 2013 | F15: I | G15: Net Market Income | H15: Yes | I15: Yes | J15: Yes (fuel tax) | K15: No | L15: Insurance value - Intermediate | M15: 9354.6 | N15: 21600 | O15: 17256219 | P15: 137212064000000 | Q15: Encuesta de Caracterización Socioeconómica Nacional 2013
A16: =A15+1 -> 9 | B16: Colombia (2010) | C16: 2010 | D16: 2010 | E16: CEQHB 2018 | F16: I | G16: Market Income | H16: Yes | I16: Yes | J16: No | K16: No | L16: Insurance value - Intermediate | M16: 3821 | N16: 10160 | O16: 45062798 | P16: 544924000000000 | Q16: Encuesta Nacional de Calidad de Vida 2010
B17: Colombia (2014) | C17: 2014 | D17: 2014 | E17: CEQHB 2018 | F17: I | G17: Market Income | H17: Yes | I17: Yes | J17: No | K17: No | L17: Insurance value - Intermediate | N17: 12940 | O17: 47203862 | P17: 756152000000000 | Q17: Encuesta Nacional de Calidad de Vida 2014
A18: =A16+1 -> 10 | B18: *,** Comoros (2014) | C18: 2014 | E18: CEQHB 2013 | F18: C | G18: Disposable Income | H18: Yes | I18: Yes | N18: 2529 | O18: 747155 | P18: 425713000000 | Q18: Enquête sur l’emploi, le secteur informel et la consommation des ménages aux Comores 2014
A19: =A18+1 -> 11 | B19: Costa Rica (2010) | C19: 2010 | D19: 2010 | E19: CEQHB 2011 | F19: I | G19: Market Income | H19: No | J19: No | K19: No | L19: Insurance value - Access | M19: 5393.6 | N19: 12320 | O19: 4551553 | P19: 19086721000000 | Q19: Encuesta Nacional de Hogares 2010
A20: =A19+1 -> 12 | B20: *,** Croatia (2014) | C20: 2014 | D20: 2014 | E20: CEQHB 2018 | F20: I | G20: Net Market Income | H20: No | J20: No | K20: No | L20: Insurance value - Access | N20: 21640 | O20: 4238389 | P20: 3.3156965e+11 | Q20: Croatian Household Budget Survey
A21: =A20+1 -> 13 | B21: Dominican Republic (2006) | C21: 2006-07 | D21: 2013 | E21: CEQHB 2018 | F21: I | G21: Market Income | H21: Yes | I21: Yes | J21: No | K21: No | L21: Insurance value - Access & Intermediate | N21: 11770 | O21: 9234446 | P21: 2590678302100 | Q21: Encuesta Nacional de Ingresos y Gastos de los Hogares 2006-2007
A22: =A21+1 -> 14 | B22: Ecuador (2011) | C22: 2011-12 | D22: 2011 | E22: CEQHB 2013 | F22: I | G22: Market Income | H22: No | I22: Yes | J22: No | K22: No | L22: Insurance value - Intermediate | M22: 3421.4 | N22: 9770 | O22: 15223535 | P22: 79276664000 | Q22: Encuesta Nacional de Ingresos y Gastos de los Hogares Urbanos y Rurales 2011-2012
A23: =A22+1 -> 15 | B23: *,** Egypt (2015) | C23: 2015 | D23: 2015 | E23: CEQHB 2018 | F23: C | G23: Disposable Income | H23: Yes | I23: Yes | J23: Yes | K23: Yes | N23: 10068.822 | O23: 92442547 | P23: 2443900000000 | Q23: Household Income, Expenditure, and Consumption Survey
A24: =A23+1 -> 16 | B24: El Salvador (2011) | C24: 2011 | D24: 2011 | E24: CEQHB 2018 | F24: I | G24: Market Income | H24: Yes | I24: Yes | J24: No | K24: No | L24: Insurance value - Intermediate | M24: 3016.3 | N24: 6310 | O24: 6213730 | P24: 20283780000 | Q24: Encuesta de Hogares de Propositos Multiples 2011
A25: =A24+1 -> 17 | B25: Ethiopia (2010) | C25: 2010-11 | D25: 2011 | E25: CEQHB 2013 | F25: C | G25: Disposable Income | H25: Yes | I25: Yes | J25: Yes | K25: No | L25: Insurance value - Access | N25: 1160 | O25: 76073949 | P25: 505646000000 | Q25: Household Consumption Expediture Survey 2010 -2011 and Welfare Monitoring Survey 2010-2011
A26: =A25+1 -> 18 | B26: Georgia (2013) | C26: 2013 | D26: 2013 | E26: CEQHB 2013 | F26: I | G26: Net Market Income | H26: Yes | I26: Yes | J26: No | K26: No | L26: Insurance value - Intermediate | M26: 2119.1 | N26: 8530 | O26: 3675078 | P26: 2.6847354e+10 | Q26: Integrated Household Survey 2013
A27: =A26+1 -> 19 | B27: Ghana (2012) | C27: 2012-13 | D27: 2013 | E27: CEQHB 2018 | F27: C | G27: Disposable Income | H27: Yes | I27: No | J27: Yes (import duties and fuel excises on petrol and diesel) | K27: Yes (electricity subsidy) | L27: Actual Use | N27: 3860 | O27: 26347424 | P27: 93415886300 | Q27: Living Standards Survey, Round 6 2012-2013
A28: =A27+1 -> 20 | B28: Guatemala (2011) | C28: 2011 | D28: 2011 | E28: CEQHB 2013 | F28: I | G28: Net Market Income | H28: Yes | I28: Yes | J28: No | K28: No | L28: Insurance value - Access | M28: 2174.1 | N28: 6630 | O28: 14636886 | P28: 371278000000 | Q28: Encuesta Nacional de Condiciones de Vida 2011
A29: =A28+1 -> 21 | B29: *,** Guinea (2012) | C29: 2012 | D29: 2016 | E29: CEQHB 2018 | N29: 1620 | O29: 10652029 | P29: 5.3358078e+13 | Q29: Enquête Légère pour l’Evaluation de la Pauvreté 2012
A30: =A29+1 -> 22 | B30: Honduras (2011) | C30: 2011 | D30: 2011 | E30: CEQHB 2013 | F30: I | G30: Market Income | H30: No | I30: Yes | J30: No | K30: No | L30: Insurance value - Basic | M30: 1490.7 | N30: 3820 | O30: 8171770 | P30: 335027800000 | Q30: Encuesta Permanente de Hogares de Propositos Multiples 2011
A31: =A30+1 -> 23 | B31: Indonesia (2012) | C31: 2012 | D31: 2012 | E31: CEQHB 2013 | F31: C | G31: Disposable Income | H31: Yes | I31: Yes | J31: Yes | K31: Yes | L31: Insurance value - Access | M31: 1668.6 | N31: 9160 | O31: 245265690 | P31: 8.2418643e+15 | Q31: Survei Sosial-Ekonomi Nasional 2012
A32: =A31+1 -> 24 | B32: Iran (2011) | C32: 2011-12 | D32: 2011-12 | E32: CEQHB 2013 | F32: I | G32: Market Income | H32: No | I32: Yes | J32: No | K32: No | L32: Insurance value - Access | N32: 17625 | O32: 79511694 | P32: 6.2457657e+15 | Q32: Iranian Urban and Rural Household Income and Expenditure Survey 2011-2012
A33: =A32+1 -> 25 | B33: Jordan (2010) | C33: 2010-11 | D33: 2010 | E33: CEQHB 2013 | F33: C | G33: Disposable Income | H33: Yes | I33: Yes | J33: No | K33: Yes | L33: Insurance value - Access | M33: 2807.8 | N33: 9200 | O33: 5961481.8 | P33: 1.8762019e+10 | Q33: Household Expenditure and Income Survey 2010-2011
A34: =A33+1 -> 26 | B34: *,** Kenya (2015) | C34: 2015-16 | D34: 2015-16 | E34: CEQHB 2013 | F34: C | G34: Disposable Income | K34: No | N34: 3065 | O34: 48465011 | P34: 6653574007897 | Q34: Integrated Household Budget Survey 2015-2016
A35: =A34+1 -> 27 | B35: *,** Mali (2014) | C35: 2014 | D35: 2014 | F35: C | G35: Disposable Income | J35: Yes | N35: 1920 | O35: 16934220 | P35: 7092793041100 | Q35: Enquête Agricole de Conjoncture Intégrée
A36: =A35+1 -> 28 | B36: Mexico (2010) | C36: 2010 | D36: 2010 | E36: CEQHB 2011 | F36: I | G36: Net Market Income | H36: Yes | I36: Yes | J36: No | K36: Yes (fuel subsidy) | L36: Insurance value - Intermediate | M36: 7942.5 | N36: 14660 | O36: 112600583 | P36: 13075798000000 | Q36: Encuesta Nacional de Ingresos y Gastos de los Hogares 2010
B37: Mexico (2012) | C37: 2012 | D37: 2012 | E37: CEQHB 2018 | F37: I | G37: Net Market Income | H37: Yes | I37: Yes | J37: No | K37: Yes (fuel subsidy) | L37: Insurance value - Intermediate | M37: 8534.3402 | N37: 16340 | O37: 117284429 | P37: 15626906634000 | Q37: Encuesta Nacional de Ingresos y Gastos de los Hogares 2012
B38: Mexico (2014) | C38: 2014 | D38: 2014 | E38: CEQHB 2018 | F38: I | G38: Net Market Income | H38: Yes | I38: Yes | J38: No | K38: Yes (fuel subsidy) | L38: Insurance value - Intermediate | N38: 17080 | O38: 119906312 | P38: 17259799421000 | Q38: Encuesta Nacional de Ingresos y Gastos de los Hogares 2014
A39: =A36+1 -> 29 | B39: *,** Mongolia (2016) | C39: 2016 | D39: 2016 | E39: CEQHB 2013 | F39: I | G39: Net Market Income | J39: No | K39: No | N39: 11250 | O39: 3056359 | P39: 2.3942866e+13 | Q39: Mongolia’s Household Socio Economic Survey 2016
A40: =A39+1 -> 30 | B40: *,** Namibia (2009) | C40: 2009 | D40: 2009 -10 | E40: CEQHB 2013 | N40: 7970 | O40: 2118874 | P40: 8.2599189e+10 | Q40: Household Income and Expenditure Survey
A41: =A40+1 -> 31 | B41: Nicaragua (2009) | C41: 2009 | D41: 2009 | E41: CEQHB 2013 | F41: I | G41: Net Market Income | H41: Yes | I41: Yes | J41: No | K41: No | L41: Insurance value - Access | M41: 3876.2756 | N41: 3660 | O41: 5765733 | P41: 1.9088798e+11 | Q41: Encuesta Nacional de Medicion de Nivel de Vida 2009
A42: =A41+1 -> 32 | B42: *,** Niger (2014) | C42: 2014 -15 | D42: 2014 | N42: 800 | O42: 17114761 | P42: 3024277000000 | Q42: Enquête nationale sur les Conditions de Vie des Ménages et Agriculture
...

Sheet 4.Taxes and transfers- ShareGDP
A1: Go to Contents
B3: Taxes and transfers as a share of GDP
B4: NOTE: FOR SOURCES AND CITATIONS SEE BOTTOM OF PAGE
B6: Country | C6: Year of survey | D6: Year of budgetary data and fiscal system | F6: Population | G6: GDP (current LCU) | I6: Revenues as a share of GDP | AA6: Spending as a share of GDP
I7: Total revenues | J7: Taxes | AA7: Total spending | AB7: Primary spending | AC7: Social spending | AI7: Social insurance | AK7: Non social spending
J8: Total taxes | K8: Total tax burden on households *** | L8: Direct taxes | Q8: Indirect taxes | V8: Other taxes | X8: Social security contributions | Y8: Other revenues | AC8: Total social spending | AD8: Direct transfers | AE8: Education | AF8: Health | AG8: Other | AI8: Contributory pensions | AK8: Subsidies | AM8: Social spending plus contributory pensions | AN8: Social spending plus subsidies | AO8: Social spending plus contributory pensions plus subsidies
L9: Total direct taxes | M9: Personal and payroll taxes | N9: Corporate taxes | O9: Other direct taxes | Q9: Total indirect taxes | R9: VAT | S9: Excises | T9: Other indirect taxes
A10: =A9+1 -> 1 | B10: *,** Albania (2015) | C10: 2015 | D10: 2015 | F10: 2880703 | G10: 1434307000000 | I10: 0.276 | J10: 0.247 | K10: =M10+R10+S10+X10 -> 0.144 | L10: =SUM(M10:O10) -> 0.042 | M10: 0.022 | N10: 0.017 | O10: 0.003 | Q10: =SUM(R10:T10) -> 0.126 | R10: 0.091 | S10: 0.031 | T10: 0.004 | V10: 0.079 | Y10: 0.029 | AA10: 0.3279 | AC10: 0.0912 | AE10: 0.028 | AF10: 0.0284 | AG10: 0.035 | AM10: 0.0912 | AN10: 0.0912 | AO10: 0.0912
A11: =A10+1 -> 2 | B11: Argentina (2012) | C11: 2012-13 | D11: 2012 | F11: 36138213 | G11: 2.6379138e+12 | I11: 0.33183965 | J11: 0.23902206 | K11: 0.19606944 | L11: 0.083566774 | M11: 0.020575947 | N11: 0.030511307 | O11: 0.03247952 | Q11: 0.15274806 | R11: 0.072214807 | S11: 0.015466867 | T11: 0.065066382 | V11: 0.002707233 | X11: 0.087811817 | Y11: 0.0050057738 | AA11: 0.44137635 | AB11: 0.42086625 | AC11: 0.20900823 | AD11: 0.057963499 | AE11: 0.074759746 | AF11: 0.05648677 | AG11: 0.019798213 | AI11: 0.071007071 | AK11: 0.059338458 | AM11: 0.2800153 | AN11: 0.26834669 | AO11: 0.33935376
A12: =A11+1 -> 3 | B12: Armenia (2011) | C12: 2011 | D12: 2011 | F12: 2965466.5 | G12: 3777945600000 | I12: 0.23983188 | J12: 0.17147102 | K12: 0.15154995 | L12: 0.051675043 | M12: 0.021495969 | N12: 0.025898282 | O12: 0.0042807922 | Q12: 0.11570275 | R12: 0.086947467 | S12: 0.010430135 | T12: 0.018325145 | V12: 0.0040932299 | X12: 0.032676384 | Y12: 0.035684474 | AA12: 0.26826747 | AB12: 0.25886082 | AC12: 0.077759821 | AD12: 0.025206301 | AE12: 0.035747613 | AF12: 0.016805907 | AI12: 0.042096953 | AM12: 0.11985677 | AN12: 0.077759821 | AO12: 0.11985677
A13: =A12+1 -> 4 | B13: *,** Belarus (2015) | C13: 2015 | D13: 2016 | F13: 9489616 | G13: 89909810000 | I13: 0.433 | J13: 0.368 | K13: =M13+R13+S13+X13 -> 0.261 | L13: 0.084 | M13: 0.043 | N13: 0.027 | O13: 0.014 | Q13: 0.171 | R13: 0.084 | S13: 0.022 | T13: 0.065 | V13: 0.001 | X13: 0.112 | Y13: 0.065 | AA13: 0.41 | AE13: 0.048 | AF13: 0.045 | AI13: 0.096 | AK13: 0.03
A14: =A13+1 -> 5 | B14: Bolivia (2009) | C14: 2009 | D14: 2009 | F14: 10232625 | G14: 1.2172675e+11 | I14: 0.31495206 | J14: 0.26795206 | K14: 0.11333558 | L14: 0.056528133 | M14: 0.00236595 | N14: 0.044558726 | O14: 0.0096034569 | Q14: 0.11096963 | V14: 0.1004543 | Y14: 0.047 | AA14: 0.34836223 | AB14: 0.333 | AC14: 0.14691085 | AD14: 0.020460335 | AE14: 0.082706475 | AF14: 0.036005303 | AG14: 0.0077387386 | AI14: 0.035431819 | AK14: 0.006 | AM14: 0.18234267 | AN14: 0.15291085 | AO14: 0.18834267
A15: =A14+1 -> 6 | B15: Brazil (2008) | C15: 2008-09 | D15: 2009 | F15: 1.905193e+08 | G15: 3333039000000 | I15: 0.36886192 | J15: 0.23974637 | K15: 0.18403052 | L15: 0.094748356 | M15: 0.020131776 | N15: 0.037383297 | O15: 0.037233284 | Q15: 0.14499801 | R15: 0.073231683 | S15: 0.0062696169 | T15: 0.065496712 | X15: 0.084397443 | Y15: 0.044718107 | AA15: 0.48899915 | AB15: 0.39548573 | AC15: 0.16629822 | AD15: 0.05397476 | AE15: 0.050764477 | AF15: 0.049808056 | AG15: 0.011750924 | AI15: 0.086588521 | AM15: 0.25288674 | AN15: 0.16629822 | AO15: 0.25288674
A16: =A15+1 -> 7 | B16: *,** Burkina Faso (2014) | C16: 2014 | D16: 2014 | F16: 17586017 | G16: 6119568000000 | I16: 0.21588779 | J16: 0.15371673 | K16: 0.084486356 | L16: 0.04412403 | M16: 0.0012108698 | N16: 0.042914794 | Q16: 0.10676407 | R16: 0.063221783 | S16: 0.020055337 | T16: 0.023488586 | V16: 0.002828631 | Y16: 0.062171055 | AA16: 0.26815128 | AC16: 0.074 | AD16: 0.006 | AE16: 0.033708262 | AF16: 0.015327879 | AI16: 0.0083 | AK16: 0.010409232 | AM16: 0.0823 | AN16: 0.084409232 | AO16: 0.092709232
A17: =A16+1 -> 8 | B17: Chile (2013) | C17: 2013 | D17: 2013 | F17: 17256219 | G17: 137212064000000 | I17: 0.21034972 | J17: 0.16748223 | K17: 0.12347426 | L17: 0.066221678 | M17: 0.013207501 | N17: 0.036917096 | O17: 0.016097081 | Q17: 0.09812806 | R17: 0.079452679 | S17: 0.016464227 | T17: 0.0022111543 | V17: 0.0031324968 | X17: 0.014349852 | Y17: 0.028517638 | AA17: 0.21648451 | AB17: 0.21065616 | AC17: 0.1106064 | AD17: 0.016424406 | AE17: 0.042867771 | AF17: 0.038077731 | AG17: 0.013240527 | AI17: 0.029256727 | AK17: 0.0048933879 | AM17: 0.13986716 | AN17: 0.11549979 | AO17: 0.14475652
A18: =A17+1 -> 9 | B18: Colombia (2010) | C18: 2010 | D18: 2010 | F18: 45062798 | G18: 544924000000000 | I18: 0.16965836 | J18: 0.13362241 | K18: 0.07529767 | L18: 0.063456993 | M18: 0.0013613385 | N18: 0.014312979 | O18: 0.047782676 | Q18: 0.069933091 | R18: 0.052872844 | T18: 0.017060248 | V18: 0.00023233041 | X18: 0.021063488 | Y18: 0.014972462 | AA18: 0.17196597 | AB18: 0.14588398 | AC18: 0.088423655 | AD18: 0.0049552121 | AE18: 0.032952355 | AF18: 0.049756533 | AG18: 0.00075955546 | AI18: 0.031398874 | AK18: 0.0053972115 | AM18: 0.11982253 | AN18: 0.093820867 | AO18: 0.12521974
B19: Colombia (2014) | C19: 2014 | D19: 2014 | F19: 47203862 | G19: 756152000000000 | I19: 0.20776858 | J19: 0.15905738 | K19: 0.087992527 | L19: 0.087552398 | M19: 0.011259451 | N19: 0.053164876 | O19: 0.023128071 | Q19: 0.07116018 | R19: 0.051246137 | T19: 0.019914043 | V19: 0.00034480014 | X19: 0.025486939 | Y19: 0.023224265 | AA19: 0.1919356 | AB19: 0.17131307 | AC19: 0.092717176 | AD19: 0.0058538098 | AE19: 0.030500739 | AF19: 0.0535464 | AG19: 0.0028162274 | AI19: 0.03632984 | AK19: 0.0046313229 | AM19: 0.12904702 | AN19: 0.097348499 | AO19: 0.13367834
A20: =A18+1 -> 10 | B20: *,** Comoros (2014) | C20: 2014 | F20: 747155 | G20: 425713000000
A21: =A20+1 -> 11 | B21: Costa Rica (2010) | C21: 2010 | D21: 2010 | F21: 4551553 | G21: 19086721000000 | I21: 0.23368647 | J21: 0.14046305 | K21: 0.15769792 | L21: 0.048158545 | M21: 0.010627735 | N21: 0.023574219 | O21: 0.013956591 | Q21: 0.092304502 | R21: 0.075212501 | T21: 0.017092 | X21: 0.07185768 | Y21: 0.021365742 | AA21: 0.27765008 | AB21: 0.25634264 | AC21: 0.16037463 | AD21: 0.011797009 | AE21: 0.065894428 | AF21: 0.062137089 | AG21: 0.020546107 | AI21: 0.04387608 | AM21: 0.20425071 | AN21: 0.16037463 | AO21: 0.20425071
A22: =A21+1 -> 12 | B22: *,** Croatia (2014) | C22: 2014 | D22: 2014 | F22: 4238389 | G22: 3.3156965e+11 | I22: 0.427 | J22: 0.249 | K22: 0.324 | L22: 0.054 | M22: 0.036 | N22: 0.017 | Q22: 0.17 | R22: 0.125 | S22: 0.036 | T22: 0.009 | V22: 0.025 | X22: 0.127 | Y22: 0.051 | AA22: 0.481 | AC22: =SUM(AD22:AG22) -> 0.173 | AD22: 0.029 | AE22: 0.043 | AF22: 0.056 | AG22: 0.045 | AI22: 0.11 | AM22: 0.283 | AN22: =AC22+AK22 -> 0.173 | AO22: =AM22+AK22 -> 0.283
A23: =A22+1 -> 13 | B23: Dominican Republic (2006) | C23: 2006-07 | D23: 2013 | F23: 9234446 | G23: 2590678302100 | I23: 0.14480645 | J23: 0.13655464 | K23: 0.082500844 | L23: 0.050502142 | M23: 0.012832755 | N23: 0.022528919 | O23: 0.015140469 | Q23: 0.086052497 | R23: 0.043745878 | S23: 0.025322957 | T23: 0.016983662 | X23: 0.00059925356 | Y23: 0.0076525532 | AA23: 0.1706616 | AB23: 0.15098328 | AC23: 0.079413113 | AD23: 0.0079258299 | AE23: 0.037122297 | AF23: 0.018129651 | AG23: 0.016235336 | AI23: 0.0083618282 | AK23: 0.013295175 | AM23: 0.087774942 | AN23: 0.092708288 | AO23: 0.10107012
A24: =A23+1 -> 14 | B24: Ecuador (2011) | C24: 2011-12 | D24: 2011 | F24: 15223535 | G24: 79276664000 | I24: 0.25446898 | J24: 0.12399653 | K24: 0.11397067 | L24: 0.048896526 | M24: 0.0037982127 | N24: 0.034183914 | O24: 0.010914399 | Q24: 0.0751 | R24: 0.0527 | S24: 0.0077 | T24: 0.0147 | X24: 0.049772455 | Y24: 0.0807 | AA24: 0.2311 | AB24: 0.22263474 | AC24: 0.092582468 | AD24: 0.012237798 | AE24: 0.045 | AF24: 0.032786788 | AG24: 0.0025578826 | AI24: 0.031087962 | AK24: 0.03983085 | AM24: 0.12367043 | AN24: 0.13241332 | AO24: 0.16350128
A25: =A24+1 -> 15 | B25: *,** Egypt (2015) | C25: 2015 | D25: 2015 | F25: 92442547 | G25: 2443900000000 | I25: 0.19 | J25: 0.125 | K25: =M25+R25+S25+X25 -> 0.06 | L25: 0.062 | M25: 0.016 | N25: 0.037 | O25: 0.009 | Q25: 0.063 | R25: 0.027 | S25: 0.017 | T25: 0.02 | Y25: 0.065 | AA25: 0.3 | AC25: 0.0751 | AD25: 0.0221 | AE25: 0.038 | AF25: 0.015 | AI25: 0.014 | AK25: 0.041 | AM25: =AC25+AI25 -> 0.0891 | AN25: =AC25+AK25 -> 0.1161 | AO25: =AM25+AK25 -> 0.1301
A26: =A25+1 -> 16 | B26: El Salvador (2011) | C26: 2011 | D26: 2011 | F26: 6209818 | G26: 20283780000 | I26: =J26+X26+Y26 -> 0.20805673 | J26: =L26+Q26+V26 -> 0.15810549 | K26: =M26+R26+S26 -> 0.11795484 | L26: =SUM(M26:O26) -> 0.056357691 | M26: 0.024469798 | N26: 0.031084295 | O26: 0.00080359775 | Q26: =SUM(R26:T26) -> 0.1017478 | R26: 0.077605358 | S26: 0.015879683 | T26: 0.0082627597 | X26: 0.01899005 | Y26: =2.04187779595322%+1.05424136921225% -> 0.030961192 | AA26: 0.25275466 | AB26: 0.22722244 | AC26: =SUM(AD26:AF26) -> 0.090136594 | AD26: 0.0078379013 | AE26: 0.033407411 | AF26: 0.048891282 | AI26: 0.01999578 | AK26: 0.020877371 | AM26: =AC26+AI26 -> 0.11013237 | AN26: =AC26+AK26 -> 0.11101396 | AO26: =AM26+AK26 -> 0.13100974
A27: =A26+1 -> 17 | B27: Ethiopia (2010) | C27: 2010-11 | D27: 2011 | F27: 76073949 | G27: 505646000000 | I27: 0.16932157 | J27: 0.1166554 | K27: 0.089322684 | L27: 0.038671459 | M27: 0.011338741 | N27: 0.019885857 | O27: 0.0074468603 | Q27: 0.077983943 | R27: 0.030206104 | S27: 0.047777839 | Y27: 0.052666166 | AA27: 0.18556739 | AB27: 0.18178411 | AC27: 0.079777884 | AD27: 0.013454729 | AE27: 0.046168663 | AF27: 0.012473056 | AG27: 0.0076814358 | AI27: 0.0047464036 | AK27: 0.0054247438 | AM27: 0.084524288 | AN27: 0.085202628 | AO27: 0.089949032
A28: =A27+1 -> 18 | B28: Georgia (2013) | C28: 2013 | D28: 2013 | F28: 3675078 | G28: 2.6847354e+10 | I28: 0.27691958 | J28: 0.24805268 | K28: 0.2050299 | L28: 0.11069304 | M28: 0.072049661 | N28: 0.030041892 | O28: 0.0086014876 | Q28: 0.13630925 | R28: 0.10607628 | S28: 0.026903955 | T28: 0.0033290175 | V28: 0.0010503828 | Y28: 0.028866904 | AA28: 0.28809073 | AB28: 0.27913642 | AC28: 0.12170954 | AD28: 0.061067293 | AE28: 0.027956584 | AF28: 0.018260767 | AG28: 0.014424894 | AK28: 0.020396911 | AM28: 0.12170954 | AN28: 0.14210645 | AO28: 0.14210645
A29: =A28+1 -> 19 | B29: Ghana (2012) | C29: 2012-13 | D29: 2013 | F29: 26347424 | G29: 93415886300 | I29: 0.20863963 | J29: 0.14572741 | K29: 0.081423958 | L29: 0.067451054 | M29: 0.027286579 | N29: 0.029266971 | O29: 0.010897504 | Q29: 0.07827636 | R29: 0.035508553 | S29: 0.0092942244 | T29: 0.033473582 | X29: 0.0093346007 | Y29: 0.053577611 | AA29: 0.286 | AB29: 0.23905998 | AC29: 0.074538173 | AD29: 0.00074933721 | AE29: 0.056542845 | AF29: 0.016645991 | AG29: 0.0006 | AI29: 0.013209745 | AK29: 0.0132 | AM29: 0.087747918 | AN29: 0.087738173 | AO29: 0.10094792
A30: =A29+1 -> 20 | B30: Guatemala (2011) | C30: 2011 | D30: 2011 | F30: 14636886 | G30: 371278000000 | I30: 0.12854547 | J30: 0.10852295 | K30: 0.074114754 | L30: 0.034234414 | M30: 0.0039395163 | N30: 0.023164909 | O30: 0.0071299886 | Q30: 0.074288539 | R30: 0.052446415 | S30: 0.0021089319 | T30: 0.019733192 | X30: 0.015619891 | Y30: 0.0044026309 | AA30: 0.16257745 | AB30: 0.14782921 | AC30: 0.068681462 | AD30: 0.0040469002 | AE30: 0.027104971 | AF30: 0.021374604 | AG30: 0.016154987 | AI30: 0.0029679892 | AK30: 0.003885091 | AM30: 0.071649452 | AN30: 0.072566553 | AO30: 0.075534543
A31: =A30+1 -> 21 | B31: *,** Guinea (2012) | C31: 2012 | D31: 2016 | F31: 10652029 | G31: 5.3358078e+13 | I31: 0.178 | J31: 0.17 | L31: 0.027 | Q31: 0.112 | R31: 0.076 | T31: 0.036 | V31: 0.031 | Y31: 0.008
A32: =A31+1 -> 22 | B32: Honduras (2011) | C32: 2011 | D32: 2011 | F32: 8171770 | G32: 335027800000 | I32: 0.14988099 | J32: 0.14723883 | K32: 0.063854999 | L32: 0.051541693 | M32: 0.00097126268 | N32: 0.0076363812 | O32: 0.042934049 | Q32: 0.095697133 | R32: 0.056543666 | S32: 0.0057359419 | T32: 0.033417525 | X32: 0.00060412897 | Y32: 0.0020380398 | AA32: 0.216 | AB32: 0.202 | AC32: 0.10018874 | AD32: 0.0039602684 | AE32: 0.060844413 | AF32: 0.03533093 | AG32: 5.3129919e-05 | AI32: 0.00060412897 | AK32: 0.0038784841 | AM32: 0.10079287 | AN32: 0.10406723 | AO32: 0.10467135
A33: =A32+1 -> 23 | B33: Indonesia (2012) | C33: 2012 | D33: 2012 | F33: 245265690 | G33: 8.2418643e+15 | I33: 0.16237989 | J33: 0.11896738 | K33: 0.065274244 | L33: 0.059942386 | M33: 0.011896697 | N33: 0.044530949 | O33: 0.00351474 | Q33: 0.058514188 | R33: 0.040959665 | S33: 0.011529794 | T33: 0.0060247291 | V33: 0.00051080676 | X33: 0.00088808766 | Y33: 0.04252442 | AA33: 0.17471775 | AB33: 0.162 | AC33: 0.048579322 | AD33: 0.0038806972 | AE33: 0.033997163 | AF33: 0.0088450862 | AG33: 0.0018563761 | AI33: 0.0075851552 | AK33: 0.040774755 | AM33: 0.056164477 | AN33: 0.089354077 | AO33: 0.096939233
A34: =A33+1 -> 24 | B34: Iran (2011) | C34: 2011-12 | D34: 2011-12 | F34: 79511694 | G34: 6.2457657e+15 | I34: 0.27040783 | J34: 0.065407834 | K34: 0.01518946 | L34: 0.038609378 | M34: 0.0085370579 | N34: 0.027874842 | O34: 0.0021974784 | Q34: 0.026798456 | R34: 0.0066323883 | S34: 2.0013559e-05 | T34: 0.020146054 | Y34: 0.205 | AA34: 0.27 | AB34: 0.26867645 | AC34: 0.1154 | AD34: 0.0399 | AE34: 0.0448 | AF34: 0.025 | AG34: 0.0057 | AI34: 0.0216 | AM34: 0.137 | AN34: 0.1154 | AO34: 0.137
A35: =A34+1 -> 25 | B35: Jordan (2010) | C35: 2010-11 | D35: 2010 | F35: 5961481.8 | G35: 1.8762019e+10 | I35: 0.24796382 | J35: 0.15748849 | K35: 0.1151423 | L35: 0.03329066 | M35: 0.0081174631 | N35: 0.025173197 | Q35: 0.10592154 | R35: 0.10592154 | V35: 0.018276284 | X35: 0.0011032928 | Y35: 0.08937204 | AA35: 0.30423164 | AB35: 0.283 | AC35: 0.091066264 | AD35: 0.0072486867 | AE35: 0.031833194 | AF35: 0.030977476 | AG35: 0.021006907 | AI35: 0.039707879 | AK35: 0.010190801 | AM35: 0.13077414 | AN35: 0.10125706 | AO35: 0.14096494
A36: =A35+1 -> 26 | B36: *,** Kenya (2015) | C36: 2015-16 | D36: 2015-16 | F36: 48465011 | G36: 6653574007897 | J36: 0.17 | K36: 0.107 | L36: 0.086 | M36: 0.043 | N36: 0.042 | O36: 0.001 | Q36: 0.084 | R36: 0.043 | S36: 0.021 | T36: 0.02 | AE36: 0.176 | AF36: 0.019
A37: =A36+1 -> 27 | B37: *,** Mali (2014) | C37: 2014 | D37: 2014 | F37: 16934220 | G37: 7092793041100 | I37: 0.171 | J37: 0.126 | AA37: 0.211 | AF37: 0.012 | AK37: 0.012
A38: =A37+1 -> 28 | B38: Mexico (2010) | C38: 2010 | D38: 2010 | F38: 112600583 | G38: 13075798000000 | I38: 0.1694897 | J38: 0.098499272 | K38: 0.087555216 | L38: 0.05084564 | M38: 0.02227552 | N38: 0.02857012 | Q38: 0.044114984 | R38: 0.037744652 | S38: 0.0045350441 | T38: 0.0018352878 | V38: 0.0035386477 | X38: 0.023 | Y38: 0.047990423 | AC38: 0.098174209 | AD38: 0.009645581 | AE38: 0.045435319 | AF38: 0.030575475 | AG38: 0.012517834 | AI38: 0.0258 | AK38: 0.014 | AM38: 0.12397421 | AN38: 0.11217421 | AO38: 0.13797421
B39: Mexico (2012) | C39: 2012 | D39: 2012 | F39: 117284429 | G39: 15626906634000 | I39: 0.17671517 | J39: 0.095937962 | K39: 0.087538612 | L39: 0.050822381 | M39: 0.023852625 | N39: 0.026969755 | Q39: 0.043043175 | R39: 0.036666862 | S39: 0.0046120892 | T39: 0.0017642236 | V39: 0.0020724053 | X39: 0.022407035 | Y39: 0.058370172 | AA39: 0.18116591 | AB39: 0.16492192 | AC39: 0.087542544 | AD39: 0.009573814 | AE39: 0.045266749 | AF39: 0.032701981 | AI39: 0.021376147 | AK39: 0.019315175 | AM39: 0.10891869 | AN39: 0.10709361 | AO39: 0.12846976
B40: Mexico (2014) | C40: 2014 | D40: 2014 | F40: 119906312 | G40: 17259799421000 | I40: 0.17258429 | J40: 0.10420764 | K40: 0.096092994 | L40: 0.054937399 | M40: 0.027077347 | N40: 0.027860052 | Q40: 0.047248833 | R40: 0.038181397 | S40: 0.0071255377 | T40: 0.0019418975 | V40: 0.00202141 | X40: 0.023708712 | Y40: 0.044667937 | AA40: 0.1931913 | AB40: 0.17648707 | AC40: 0.08846437 | AD40: 0.0097817568 | AE40: 0.047786005 | AF40: 0.030896609 | AI40: 0.023734616 | AK40: 0.0068935177 | AM40: 0.11219899 | AN40: 0.095357888 | AO40: 0.1190925
A41: =A38+1 -> 29 | B41: *,** Mongolia (2016) | C41: 2016 | D41: 2016 | F41: 3056359 | G41: 2.3942866e+13 | I41: =J41+X41 -> 0.243 | J41: 0.194 | K41: =M41+R41+S41 -> 0.097 | L41: 0.046 | M41: 0.023 | N41: 0.021 | O41: 0.004 | Q41: 0.088 | R41: 0.048 | S41: 0.026 | T41: 0.014 | V41: 0.06 | X41: 0.049 | AC41: =SUM(AD41:AF41) -> 0.173 | AD41: 0.089 | AE41: 0.056 | AF41: 0.028 | AM41: =AC41+AI41 -> 0.173 | AN41: =AC41+AK41 -> 0.173 | AO41: =AM41+AK41 -> 0.173
A42: =A41+1 -> 30 | B42: *,** Namibia (2009) | C42: 2009 | D42: 2009 -10 | F42: 2118874 | G42: 8.2599189e+10 | I42: 0.32 | J42: 0.295 | K42: =M42+R42+S42 -> 0.134 | L42: 0.112 | M42: 0.068 | N42: 0.038 | O42: 0.006 | Q42: 0.067 | R42: 0.066 | T42: 0.001 | V42: 0.116 | Y42: 0.025 | AA42: 0.147 | AB42: 0.147 | AC42: =SUM(AD42:AG42) -> 0.127 | AD42: 0.016 | AE42: 0.075 | AF42: 0.033 | AG42: 0.003 | AK42: 0.006 | AM42: =AC42+AI42 -> 0.127 | AN42: =AC42+AK42 -> 0.133 | AO42: =AM42+AK42 -> 0.133
...

Sheet 5.Inequality - Gini coefficient
A1: Go to Contents
B3: Inequality - Gini coefficient
B4: NOTE: FOR SOURCES AND CITATIONS SEE BOTTOM OF PAGE
B6: Country | C6: Year of survey | D6: Year of budgetary data and fiscal system | F6: Contributory pensions as deferred income | K6: Contributory pensions as government transfer
F7: Market income plus pensions | G7: Disposable income | H7: Consumable income | I7: Final income | K7: Market income | L7: Disposable income | M7: Consumable income | N7: Final income
A8: =A7+1 -> 1 | B8: *,** Albania (2015) | C8: 2015 | D8: 2015 | F8: 0.3693 | G8: 0.3452 | H8: 0.3453 | I8: 0.317 | K8: 0.4742 | L8: 0.3452 | M8: 0.3453 | N8: 0.317
A9: =A8+1 -> 2 | B9: Argentina (2012) | C9: 2012-13 | D9: 2012 | F9: 0.4749556 | G9: 0.4046247 | H9: 0.4105455 | I9: 0.2986643 | K9: 0.501804 | L9: 0.4037833 | M9: 0.4097137 | N9: 0.2975485
A10: =A9+1 -> 3 | B10: Armenia (2011) | C10: 2011 | D10: 2011 | F10: 0.4044213 | G10: 0.37525667 | H10: 0.37675151 | I10: 0.35813615 | K10: 0.4700838 | L10: 0.37525667 | M10: 0.37675151 | N10: 0.35813615
A11: =A10+1 -> 4 | B11: *,** Belarus (2015) | C11: 2015 | D11: 2016 | F11: 0.292 | G11: 0.267 | H11: 0.27 | I11: 0.227 | K11: 0.407 | L11: 0.267 | M11: 0.27 | N11: 0.227
A12: =A11+1 -> 5 | B12: Bolivia (2009) | C12: 2009 | D12: 2009 | F12: 0.503 | G12: 0.493 | H12: 0.5028 | I12: 0.446 | K12: 0.5025 | L12: 0.493 | M12: 0.5028 | N12: 0.446
A13: =A12+1 -> 6 | B13: Brazil (2008) | C13: 2008-09 | D13: 2009 | F13: 0.57301587 | G13: 0.54460712 | H13: 0.54196905 | I13: 0.47931725 | K13: 0.59323816 | L13: 0.54460712 | M13: 0.54196905 | N13: 0.47931725
A14: =A13+1 -> 7 | B14: *,** Burkina Faso (2014) | C14: 2014 | D14: 2014 | F14: 0.3635 | G14: 0.353 | H14: 0.3539 | I14: 0.3283 | K14: 0.3667 | L14: 0.353 | M14: 0.3539 | N14: 0.3283
A15: =A14+1 -> 8 | B15: Chile (2013) | C15: 2013 | D15: 2013 | F15: 0.49359692 | G15: 0.46684199 | H15: 0.46409278 | I15: 0.41959384 | K15: 0.50284354 | L15: 0.46676243 | M15: 0.46400819 | N15: 0.41948503
A16: =A15+1 -> 9 | B16: Colombia (2010) | C16: 2010 | D16: 2010 | F16: 0.57761229 | G16: 0.56653029 | H16: 0.55869628 | I16: 0.51327697 | K16: 0.57498707 | L16: 0.56653029 | M16: 0.55869628 | N16: 0.51327697
B17: Colombia (2014) | C17: 2014 | D17: 2014 | F17: 0.57526175 | G17: 0.56551802 | H17: 0.55923427 | I17: 0.51464942 | K17: 0.57457582 | L17: 0.56551802 | M17: 0.55923427 | N17: 0.51464942
A18: =A16+1 -> 10 | B18: *,** Comoros (2014) | C18: 2014 | F18: 0.437 | H18: 0.45 | I18: 0.404
A19: =A18+1 -> 11 | B19: Costa Rica (2010) | C19: 2010 | D19: 2010 | F19: 0.508 | G19: 0.489 | H19: 0.486 | I19: 0.402 | K19: 0.512 | L19: 0.488 | M19: 0.485 | N19: 0.4
A20: =A19+1 -> 12 | B20: *,** Croatia (2014) | C20: 2014 | D20: 2014 | F20: 0.39179141 | G20: 0.325 | H20: 0.355 | I20: 0.291 | K20: 0.513 | L20: 0.325 | M20: 0.355 | N20: 0.291
A21: =A20+1 -> 13 | B21: Dominican Republic (2006) | C21: 2006-07 | D21: 2013 | F21: 0.5166611 | G21: 0.5053576 | H21: 0.49509696 | I21: 0.46501155 | K21: 0.51729887 | L21: 0.5053576 | M21: 0.49509696 | N21: 0.46501155
A22: =A21+1 -> 14 | B22: Ecuador (2011) | C22: 2011-12 | D22: 2011 | F22: 0.47850555 | G22: 0.45701572 | H22: 0.44568938 | I22: 0.40462824 | K22: 0.48233714 | L22: 0.45212875 | M22: 0.44085193 | N22: 0.40016075
A23: =A22+1 -> 15 | B23: *,** Egypt (2015) | C23: 2015 | D23: 2015 | F23: 0.325 | G23: 0.307 | H23: 0.299 | I23: 0.281
A24: =A23+1 -> 16 | B24: El Salvador (2011) | C24: 2011 | D24: 2011 | F24: 0.44114552 | G24: 0.42091392 | H24: 0.41063727 | I24: 0.38339826 | K24: 0.43813338 | L24: 0.42091392 | M24: 0.41063727 | N24: 0.38339826
A25: =A24+1 -> 17 | B25: Ethiopia (2010) | C25: 2010-11 | D25: 2011 | F25: 0.32167086 | G25: 0.30468106 | H25: 0.30187649 | I25: 0.29906484
A26: =A25+1 -> 18 | B26: Georgia (2013) | C26: 2013 | D26: 2013 | K26: 0.50744782 | L26: 0.39486926 | M26: 0.41130303 | N26: 0.38303767
A27: =A26+1 -> 19 | B27: Ghana (2012) | C27: 2012-13 | D27: 2013 | F27: 0.43698289 | G27: 0.42367803 | H27: 0.42328982 | I27: 0.40213141
A28: =A27+1 -> 20 | B28: Guatemala (2011) | C28: 2011 | D28: 2011 | F28: 0.512876 | G28: 0.504953 | H28: 0.505832 | I28: 0.489362 | K28: 0.511437 | L28: 0.503084 | M28: 0.503949 | N28: 0.487376
A29: =A28+1 -> 21 | B29: *,** Guinea (2012) | C29: 2012 | D29: 2016 | K29: 0.319 | L29: 0.317 | M29: 0.319 | N29: 0.317
A30: =A29+1 -> 22 | B30: Honduras (2011) | C30: 2011 | D30: 2011 | F30: 0.564099 | G30: 0.5566494 | H30: 0.551806 | I30: 0.5380545 | K30: 0.5612189 | L30: 0.556317 | M30: 0.5515012 | N30: 0.5377351
A31: =A30+1 -> 23 | B31: Indonesia (2012) | C31: 2012 | D31: 2012 | F31: 0.39826859 | G31: 0.38988379 | H31: 0.39062523 | I31: 0.37047561 | K31: 0.3944 | L31: 0.3893 | M31: 0.39 | N31: 0.3698477
A32: =A31+1 -> 24 | B32: Iran (2011) | C32: 2011-12 | D32: 2011-12 | F32: 0.42856971 | G32: 0.36860859 | H32: 0.37124157 | I32: 0.34317052
A33: =A32+1 -> 25 | B33: Jordan (2010) | C33: 2010-11 | D33: 2010 | F33: 0.34151424 | G33: 0.32833663 | H33: 0.32543258 | I33: 0.31855528 | K33: 0.3505 | L33: 0.3283 | M33: 0.3254 | N33: 0.3186
A34: =A33+1 -> 26 | B34: *,** Kenya (2015) | C34: 2015-16 | D34: 2015-16 | F34: 0.362 | G34: 0.336 | H34: 0.328 | I34: 0.297
A35: =A34+1 -> 27 | B35: *,** Mali (2014) | C35: 2014 | D35: 2014 | K35: 0.491 | L35: 0.486 | M35: 0.482 | N35: 0.469
A36: =A35+1 -> 28 | B36: Mexico (2010) | C36: 2010 | D36: 2010 | F36: 0.51067918 | G36: 0.48764237 | H36: 0.48088023 | I36: 0.42938942 | K36: 0.50873534 | L36: 0.48764237 | M36: 0.48065147 | N36: 0.42918418
B37: Mexico (2012) | C37: 2012 | D37: 2012 | F37: 0.52389439 | G37: 0.49286862 | H37: 0.48632189 | I37: 0.43993635 | K37: 0.52099103 | L37: 0.49286862 | M37: 0.48632189 | N37: 0.43993635
B38: Mexico (2014) | C38: 2014 | D38: 2014 | F38: 0.52801653 | G38: 0.49432719 | H38: 0.48998956 | I38: 0.44169476 | K38: 0.52772937 | L38: 0.49432719 | M38: 0.48998956 | N38: 0.44169476
A39: =A36+1 -> 29 | B39: *,** Mongolia (2016) | C39: 2016 | D39: 2016 | K39: 0.4183 | L39: 0.3626 | M39: 0.3752 | N39: 0.3507
A40: =A39+1 -> 30 | B40: *,** Namibia (2009) | C40: 2009 | D40: 2009 -10 | F40: 0.635 | G40: 0.594 | H40: 0.59 | I40: 0.429
A41: =A40+1 -> 31 | B41: Nicaragua (2009) | C41: 2009 | D41: 2009 | F41: 0.48176913 | G41: 0.46724375 | H41: 0.46482961 | I41: 0.43466658 | K41: 0.48196262 | L41: 0.46803349 | M41: 0.46566141 | N41: 0.43534372
A42: =A41+1 -> 32 | B42: *,** Niger (2014) | C42: 2014 -15 | D42: 2014 | K42: 0.337 | L42: 0.327 | M42: 0.326 | N42: 0.318
...

Sheet 6.Inequality - Theil index
A1: Go to Contents
B3: Inequality - Theil index
B4: NOTE: FOR SOURCES AND CITATIONS SEE BOTTOM OF PAGE
B6: Country | C6: Year of survey | D6: Year of budgetary data and fiscal system | F6: Contributory pensions as deferred income | K6: Contributory pensions as government transfer
F7: Market income plus pensions | G7: Disposable income | H7: Consumable income | I7: Final income | K7: Market income | L7: Disposable income | M7: Consumable income | N7: Final income
A8: =A7+1 -> 1 | B8: *,** Albania (2015) | C8: 2015 | D8: 2015
A9: =A8+1 -> 2 | B9: Argentina (2012) | C9: 2012-13 | D9: 2012 | F9: 0.4139067 | G9: 0.3020465 | H9: 0.328989 | I9: 0.2069367 | K9: 0.4537431 | L9: 0.3014081 | M9: 0.3286514 | N9: 0.2062115
A10: =A9+1 -> 3 | B10: Armenia (2011) | C10: 2011 | D10: 2011 | F10: 0.29351843 | G10: 0.25239742 | H10: 0.25523365 | I10: 0.23100364 | K10: 0.39353479 | L10: 0.25239742 | M10: 0.25523365 | N10: 0.23100364
A11: =A10+1 -> 4 | B11: *,** Belarus (2015) | C11: 2015 | D11: 2016 | F11: 0.15084802 | G11: 0.12936801 | H11: 0.13144089 | I11: 0.094420009 | K11: 0.25891151 | L11: 0.12936801 | M11: 0.13144089 | N11: 0.094420009
A12: =A11+1 -> 5 | B12: Bolivia (2009) | C12: 2009 | D12: 2009 | F12: 0.4969 | G12: 0.4777 | H12: 0.499 | I12: 0.3967 | K12: 0.4963 | L12: 0.4777 | M12: 0.499 | N12: 0.3967
A13: =A12+1 -> 6 | B13: Brazil (2008) | C13: 2008-09 | D13: 2009 | F13: 0.66466623 | G13: 0.5933286 | H13: 0.58647793 | I13: 0.47052721 | K13: 0.69953011 | L13: 0.5933286 | M13: 0.58647793 | N13: 0.47052721
A14: =A13+1 -> 7 | B14: *,** Burkina Faso (2014) | C14: 2014 | D14: 2014 | F14: 0.2637 | G14: 0.2424 | H14: 0.242 | I14: 0.2068 | K14: 0.2748 | L14: 0.2424 | M14: 0.242 | N14: 0.2068
A15: =A14+1 -> 8 | B15: Chile (2013) | C15: 2013 | D15: 2013 | F15: 0.49029653 | G15: 0.43300057 | H15: 0.42784733 | I15: 0.35559887 | K15: 0.51072639 | L15: 0.43300057 | M15: 0.42784733 | N15: 0.35708041
A16: =A15+1 -> 9 | B16: Colombia (2010) | C16: 2010 | D16: 2010 | F16: 0.70625479 | G16: 0.68607351 | H16: 0.66911748 | I16: 0.57320107 | K16: 0.71024334 | L16: 0.68607351 | M16: 0.66911748 | N16: 0.57320107
B17: Colombia (2014) | C17: 2014 | D17: 2014 | F17: 0.74476068 | G17: 0.72507598 | H17: 0.7159254 | I17: 0.61741439 | K17: 0.74920683 | L17: 0.72507598 | M17: 0.7159254 | N17: 0.61741439
A18: =A16+1 -> 10 | B18: *,** Comoros (2014) | C18: 2014
A19: =A18+1 -> 11 | B19: Costa Rica (2010) | C19: 2010 | D19: 2010
A20: =A19+1 -> 12 | B20: *,** Croatia (2014) | C20: 2014 | D20: 2014 | F20: 0.27000109 | G20: 0.18062743 | H20: 0.21516028 | I20: 0.14063791 | K20: 0.45802559 | L20: 0.18062743 | M20: 0.21516028 | N20: 0.14063791
A21: =A20+1 -> 13 | B21: Dominican Republic (2006) | C21: 2006-07 | D21: 2013 | F21: 0.52686511 | G21: 0.50135302 | H21: 0.47450242 | I21: 0.42455776 | K21: 0.52919688 | L21: 0.50135302 | M21: 0.47450242 | N21: 0.42455776
A22: =A21+1 -> 14 | B22: Ecuador (2011) | C22: 2011-12 | D22: 2011 | F22: 0.4519368 | G22: 0.41687091 | H22: 0.39545749 | I22: 0.33476308 | K22: 0.46152118 | L22: 0.40978988 | M22: 0.38858212 | N22: 0.32903645
A23: =A22+1 -> 15 | B23: *,** Egypt (2015) | C23: 2015 | D23: 2015
A24: =A23+1 -> 16 | B24: El Salvador (2011) | C24: 2011 | D24: 2011 | F24: 0.36127258 | G24: 0.33032167 | H24: 0.3133004 | I24: 0.27479751 | K24: 0.35555666 | L24: 0.33032167 | M24: 0.3133004 | N24: 0.27479751
A25: =A24+1 -> 17 | B25: Ethiopia (2010) | C25: 2010-11 | D25: 2011 | F25: 0.20925465 | G25: 0.18397009 | H25: 0.18027546 | I25: 0.17863119
A26: =A25+1 -> 18 | B26: Georgia (2013) | C26: 2013 | D26: 2013 | K26: 0.4543 | L26: 0.2778 | M26: 0.2934 | N26: 0.2616
A27: =A26+1 -> 19 | B27: Ghana (2012) | C27: 2012-13 | D27: 2013 | F27: 0.34386673 | G27: 0.32075623 | H27: 0.31918099 | I27: 0.28894964
A28: =A27+1 -> 20 | B28: Guatemala (2011) | C28: 2011 | D28: 2011 | F28: 0.64632 | G28: 0.631128 | H28: 0.64626 | I28: 0.606918 | K28: 0.645289 | L28: 0.629759 | M28: 0.645191 | N28: 0.605519
A29: =A28+1 -> 21 | B29: *,** Guinea (2012) | C29: 2012 | D29: 2016
A30: =A29+1 -> 22 | B30: Honduras (2011) | C30: 2011 | D30: 2011 | F30: 0.6805379 | G30: 0.6674805 | H30: 0.6644207 | I30: 0.6358788 | K30: 0.6719523 | L30: 0.6667623 | M30: 0.6638092 | N30: 0.6352507
A31: =A30+1 -> 23 | B31: Indonesia (2012) | C31: 2012 | D31: 2012 | F31: 0.3077 | G31: 0.302 | H31: 0.3012 | I31: 0.2721025 | K31: 0.308 | L31: 0.3014 | M31: 0.3006 | N31: 0.2714722
A32: =A31+1 -> 24 | B32: Iran (2011) | C32: 2011-12 | D32: 2011-12 | F32: 0.3313865 | G32: 0.24783927 | H32: 0.2513852 | I32: 0.21223875
A33: =A32+1 -> 25 | B33: Jordan (2010) | C33: 2010-11 | D33: 2010 | F33: 0.21723137 | G33: 0.19389967 | H33: 0.19107169 | I33: 0.19364638 | K33: 0.22912768 | L33: 0.19389967 | M33: 0.19107169 | N33: 0.19364638
A34: =A33+1 -> 26 | B34: *,** Kenya (2015) | C34: 2015-16 | D34: 2015-16
A35: =A34+1 -> 27 | B35: *,** Mali (2014) | C35: 2014 | D35: 2014
A36: =A35+1 -> 28 | B36: Mexico (2010) | C36: 2010 | D36: 2010
B37: Mexico (2012) | C37: 2012 | D37: 2012 | F37: 0.54711687 | G37: 0.485 | H37: 0.47 | I37: 0.39 | K37: 0.54412501 | L37: 0.48541917 | M37: 0.47003725 | N37: 0.38963626
B38: Mexico (2014) | C38: 2014 | D38: 2014 | F38: 0.5925997 | G38: 0.5222389 | H38: 0.51253777 | I38: 0.4239243 | K38: 0.59776654 | L38: 0.5222389 | M38: 0.51253777 | N38: 0.4239243
A39: =A36+1 -> 29 | B39: *,** Mongolia (2016) | C39: 2016 | D39: 2016 | K39: 0.322 | L39: 0.2434 | M39: 0.2581 | N39: 0.2557
A40: =A39+1 -> 30 | B40: *,** Namibia (2009) | C40: 2009 | D40: 2009 -10 | F40: 0.83 | G40: 0.76 | H40: 0.75 | I40: 0.385
A41: =A40+1 -> 31 | B41: Nicaragua (2009) | C41: 2009 | D41: 2009 | F41: 0.45626045 | G41: 0.42583204 | H41: 0.42395902 | I41: 0.37255926 | K41: 0.45720663 | L41: 0.42729787 | M41: 0.42548289 | N41: 0.37372405
A42: =A41+1 -> 32 | B42: *,** Niger (2014) | C42: 2014 -15 | D42: 2014
...

Sheet 7.Inequality - 90-10 ratio
A1: Go to Contents
B3: Inequality - 90/10 ratio
B4: NOTE: FOR SOURCES AND CITATIONS SEE BOTTOM OF PAGE
B6: Country | C6: Year of survey | D6: Year of budgetary data and fiscal system | F6: Contributory pensions as deferred income | K6: Contributory pensions as government transfer
F7: Market income plus pensions | G7: Disposable income | H7: Consumable income | I7: Final income | K7: Market income | L7: Disposable income | M7: Consumable income | N7: Final income
A8: =A7+1 -> 1 | B8: *,** Albania (2015) | C8: 2015 | D8: 2015
A9: =A8+1 -> 2 | B9: Argentina (2012) | C9: 2012-13 | D9: 2012 | F9: 11.00895 | G9: 6.85328 | H9: 6.90946 | I9: 3.765487 | K9: 17.94447 | L9: 6.842407 | M9: 6.846781 | N9: 3.744113
A10: =A9+1 -> 3 | B10: Armenia (2011) | C10: 2011 | D10: 2011 | F10: 8.0612256 | G10: 6.2751309 | H10: 6.3708408 | I10: 5.4855778 | K10: 21.806957 | L10: 6.2751309 | M10: 6.3708408 | N10: 5.4855778
A11: =A10+1 -> 4 | B11: *,** Belarus (2015) | C11: 2015 | D11: 2016 | F11: 3.7040852 | G11: 3.254104 | H11: 3.3165308 | I11: 2.6051263 | K11: 14.819509 | L11: 3.254104 | M11: 3.3165308 | N11: 2.6051263
A12: =A11+1 -> 5 | B12: Bolivia (2009) | C12: 2009 | D12: 2009 | F12: 14.7935 | G12: 12.3959 | H12: 13.7976 | I12: 8.1925 | K12: 14.9366 | L12: 12.3959 | M12: 13.7976 | N12: 8.1925
A13: =A12+1 -> 6 | B13: Brazil (2008) | C13: 2008-09 | D13: 2009 | F13: 16.246427 | G13: 12.868963 | H13: 12.642493 | I13: 7.3034645 | K13: 20.538376 | L13: 12.868963 | M13: 12.642493 | N13: 7.3034645
A14: =A13+1 -> 7 | B14: *,** Burkina Faso (2014) | C14: 2014 | D14: 2014 | F14: 4.18 | G14: 4.09 | H14: 4.14 | I14: 3.79 | K14: 4.16 | L14: 4.09 | M14: 4.14 | N14: 3.79
A15: =A14+1 -> 8 | B15: Chile (2013) | C15: 2013 | D15: 2013 | F15: 8.2768268 | G15: 6.877269 | H15: 6.795696 | I15: 5.1462503 | K15: 8.6917128 | L15: 6.877269 | M15: 6.795696 | N15: 5.1764703
A16: =A15+1 -> 9 | B16: Colombia (2010) | C16: 2010 | D16: 2010 | F16: 13.321492 | G16: 11.686769 | H16: 11.003238 | I16: 7.7178186 | K16: 12.899748 | L16: 11.686769 | M16: 11.003238 | N16: 7.7178186
B17: Colombia (2014) | C17: 2014 | D17: 2014 | F17: 12.858193 | G17: 11.474934 | H17: 10.977106 | I17: 7.6796113 | K17: 13.114946 | L17: 11.474934 | M17: 10.977106 | N17: 7.6796113
A18: =A16+1 -> 10 | B18: *,** Comoros (2014) | C18: 2014 | H18: 8.8
A19: =A18+1 -> 11 | B19: Costa Rica (2010) | C19: 2010 | D19: 2010
A20: =A19+1 -> 12 | B20: *,** Croatia (2014) | C20: 2014 | D20: 2014 | F20: 7.069971 | G20: 4.7009715 | H20: 5.8334298 | I20: 4.0487448 | K20: 59.300133 | L20: 4.7009715 | M20: 5.8334298 | N20: 4.0487448
A21: =A20+1 -> 13 | B21: Dominican Republic (2006) | C21: 2006-07 | D21: 2013 | F21: 10.55293 | G21: 9.8303759 | H21: 9.4238346 | I21: 7.5179177 | K21: 10.521596 | L21: 9.8303759 | M21: 9.4238346 | N21: 7.5179177
A22: =A21+1 -> 14 | B22: Ecuador (2011) | C22: 2011-12 | D22: 2011 | F22: 8.8941748 | G22: 7.5109776 | H22: 7.0428845 | I22: 5.2679813 | K22: 9.142158 | L22: 7.2832993 | M22: 6.8710005 | N22: 5.1683642
A23: =A22+1 -> 15 | B23: *,** Egypt (2015) | C23: 2015 | D23: 2015
A24: =A23+1 -> 16 | B24: El Salvador (2011) | C24: 2011 | D24: 2011 | F24: 7.6327016 | G24: 6.6228048 | H24: 6.2571839 | I24: 5.3235685 | K24: 7.5697933 | L24: 6.6228048 | M24: 6.2571839 | N24: 5.3235685
A25: =A24+1 -> 17 | B25: Ethiopia (2010) | C25: 2010-11 | D25: 2011 | F25: 3.9618945 | G25: 3.6686614 | H25: 3.6627493 | I25: 3.5155466
A26: =A25+1 -> 18 | B26: Georgia (2013) | C26: 2013 | D26: 2013 | K26: 18.7137 | L26: 6.2475 | M26: 6.9733 | N26: 5.8004
A27: =A26+1 -> 19 | B27: Ghana (2012) | C27: 2012-13 | D27: 2013 | F27: 7.5701371 | G27: 7.1996604 | H27: 7.1505083 | I27: 6.2083979
A28: =A27+1 -> 20 | B28: Guatemala (2011) | C28: 2011 | D28: 2011 | F28: 7.145436 | G28: 6.755588 | H28: 6.657371 | I28: 6.105704 | K28: 7.043408 | L28: 6.698902 | M28: 6.552021 | N28: 6.023415
A29: =A28+1 -> 21 | B29: *,** Guinea (2012) | C29: 2012 | D29: 2016
A30: =A29+1 -> 22 | B30: Honduras (2011) | C30: 2011 | D30: 2011 | F30: 15.48048 | G30: 14.05968 | H30: 13.14222 | I30: 11.39818 | K30: 15.3342 | L30: 14.0367 | M30: 13.13607 | N30: 11.38509
A31: =A30+1 -> 23 | B31: Indonesia (2012) | C31: 2012 | D31: 2012 | F31: 5.0454 | G31: 4.9157 | H31: 4.9692 | I31: 4.516526 | K31: 5.0345 | L31: 4.9009 | M31: 4.9422 | N31: 4.497878
A32: =A31+1 -> 24 | B32: Iran (2011) | C32: 2011-12 | D32: 2011-12 | F32: 8.466712 | G32: 5.3479481 | H32: 5.4450818 | I32: 4.6708357
A33: =A32+1 -> 25 | B33: Jordan (2010) | C33: 2010-11 | D33: 2010 | F33: 4.2046877 | G33: 4.0618429 | H33: 4.0094613 | I33: 3.7260417 | K33: 4.445588 | L33: 4.0618429 | M33: 4.0094613 | N33: 3.7260417
A34: =A33+1 -> 26 | B34: *,** Kenya (2015) | C34: 2015-16 | D34: 2015-16
A35: =A34+1 -> 27 | B35: *,** Mali (2014) | C35: 2014 | D35: 2014
A36: =A35+1 -> 28 | B36: Mexico (2010) | C36: 2010 | D36: 2010
B37: Mexico (2012) | C37: 2012 | D37: 2012 | F37: 11.431235 | G37: 8.8518507 | H37: 8.6389662 | I37: 6.0961224 | K37: 11.377033 | L37: 8.8518507 | M37: 8.6389662 | N37: 6.0961224
B38: Mexico (2014) | C38: 2014 | D38: 2014 | F38: 10.458887 | G38: 7.9238839 | H38: 7.7557617 | I38: 5.7980015 | K38: 10.316017 | L38: 7.924 | M38: 7.756 | N38: 5.798
A39: =A36+1 -> 29 | B39: *,** Mongolia (2016) | C39: 2016 | D39: 2016 | K39: 7.8513 | L39: 5.1933 | M39: 5.7006 | N39: 4.9468
A40: =A39+1 -> 30 | B40: *,** Namibia (2009) | C40: 2009 | D40: 2009 -10 | F40: 16.8 | G40: 10.8 | H40: 10.6 | I40: 5.9
A41: =A40+1 -> 31 | B41: Nicaragua (2009) | C41: 2009 | D41: 2009 | F41: 7.9343273 | G41: 7.5762931 | H41: 7.3367374 | I41: 6.1328911 | K41: 7.9837668 | L41: 7.5852134 | M41: 7.3470321 | N41: 6.1241419
A42: =A41+1 -> 32 | B42: *,** Niger (2014) | C42: 2014 -15 | D42: 2014
...

Sheet 8. Inequality - Absolute Gini
A1: Go to Contents
B3: Inequality - Absolute Gini
B4: NOTE: FOR SOURCES AND CITATIONS SEE BOTTOM OF PAGE
B6: Country | C6: Year of survey | D6: Year of budgetary data and fiscal system | F6: Contributory pensions as deferred income | K6: Contributory pensions as government transfer
F7: Market income plus pensions | G7: Disposable income | H7: Consumable income | I7: Final income | K7: Market income | L7: Disposable income | M7: Consumable income | N7: Final income
A8: =A7+1 -> 1 | B8: *,** Albania (2015) | C8: 2015 | D8: 2015
A9: =A8+1 -> 2 | B9: Argentina (2012) | C9: 2012-13 | D9: 2012
A10: =A9+1 -> 3 | B10: Armenia (2011) | C10: 2011 | D10: 2011 | F10: 180942.07 | G10: 166313.06 | H10: 148885.13 | I10: 148422.8 | K10: 201583.73 | L10: 166313.06 | M10: 148885.13 | N10: 148422.8
A11: =A10+1 -> 4 | B11: *,** Belarus (2015) | C11: 2015 | D11: 2016
A12: =A11+1 -> 5 | B12: Bolivia (2009) | C12: 2009 | D12: 2009
A13: =A12+1 -> 6 | B13: Brazil (2008) | C13: 2008-09 | D13: 2009 | F13: 5081 | G13: 4662.4261 | H13: 3945.5521 | I13: 3859.4746 | K13: 4683.9329 | L13: 4662.4261 | M13: 3945.5521 | N13: 3859.4746
A14: =A13+1 -> 7 | B14: *,** Burkina Faso (2014) | C14: 2014 | D14: 2014
A15: =A14+1 -> 8 | B15: Chile (2013) | C15: 2013 | D15: 2013 | F15: 1762031.6 | G15: 1635609.2 | H15: 1464046.2 | I15: 1438479.6 | K15: 1736747 | L15: 1635609.2 | M15: 1464046.2 | N15: 1438479.6
A16: =A15+1 -> 9 | B16: Colombia (2010) | C16: 2010 | D16: 2010 | F16: 3261981.9 | G16: 3077480.2 | H16: 2854182.8 | I16: 2857929.1 | K16: 3027030.5 | L16: 3077480.2 | M16: 2854182.8 | N16: 2857929.1
B17: Colombia (2014) | C17: 2014 | D17: 2014 | F17: 4131852.3 | G17: 4010260.9 | H17: 3751922.5 | I17: 3761519.4 | K17: 3876621.7 | L17: 4010260.9 | M17: 3751922.5 | N17: 3761519.4
A18: =A16+1 -> 10 | B18: *,** Comoros (2014) | C18: 2014
A19: =A18+1 -> 11 | B19: Costa Rica (2010) | C19: 2010 | D19: 2010
A20: =A19+1 -> 12 | B20: *,** Croatia (2014) | C20: 2014 | D20: 2014
A21: =A20+1 -> 13 | B21: Dominican Republic (2006) | C21: 2006-07 | D21: 2013 | F21: 37550.931 | G21: 36539.191 | H21: 33549.502 | I21: 32948.362 | K21: 37296.961 | L21: 36539.191 | M21: 33549.502 | N21: 32948.362
A22: =A21+1 -> 14 | B22: Ecuador (2011) | C22: 2011-12 | D22: 2011 | F22: 99.714133 | G22: 95.778319 | H22: 91.405696 | I22: 88.87393 | K22: 95.979729 | L22: 92.516124 | M22: 88.373176 | N22: 85.903321
A23: =A22+1 -> 15 | B23: *,** Egypt (2015) | C23: 2015 | D23: 2015
A24: =A23+1 -> 16 | B24: El Salvador (2011) | C24: 2011 | D24: 2011 | F24: 731.43916 | G24: 683.94354 | H24: 617.94971 | I24: 619.87303 | K24: 704.24966 | L24: 683.94354 | M24: 617.94971 | N24: 619.87303
A25: =A24+1 -> 17 | B25: Ethiopia (2010) | C25: 2010-11 | D25: 2011
A26: =A25+1 -> 18 | B26: Georgia (2013) | C26: 2013 | D26: 2013 | F26: . | G26: . | H26: . | I26: . | K26: . | L26: . | M26: . | N26: .
A27: =A26+1 -> 19 | B27: Ghana (2012) | C27: 2012-13 | D27: 2013 | F27: 1033.2933 | G27: 957.83362 | H27: 915.11109 | I27: 964.10176
A28: =A27+1 -> 20 | B28: Guatemala (2011) | C28: 2011 | D28: 2011
A29: =A28+1 -> 21 | B29: *,** Guinea (2012) | C29: 2012 | D29: 2016
A30: =A29+1 -> 22 | B30: Honduras (2011) | C30: 2011 | D30: 2011
A31: =A30+1 -> 23 | B31: Indonesia (2012) | C31: 2012 | D31: 2012
A32: =A31+1 -> 24 | B32: Iran (2011) | C32: 2011-12 | D32: 2011-12 | F32: 11157234 | G32: 10833725 | H32: 10562329 | I32: 10577442
A33: =A32+1 -> 25 | B33: Jordan (2010) | C33: 2010-11 | D33: 2010 | F33: 583.00252 | G33: 560.792 | H33: 557.79074 | I33: 584.32002 | K33: 565.58004 | L33: 560.792 | M33: 557.79074 | N33: 584.32002
A34: =A33+1 -> 26 | B34: *,** Kenya (2015) | C34: 2015-16 | D34: 2015-16
A35: =A34+1 -> 27 | B35: *,** Mali (2014) | C35: 2014 | D35: 2014
A36: =A35+1 -> 28 | B36: Mexico (2010) | C36: 2010 | D36: 2010
B37: Mexico (2012) | C37: 2012 | D37: 2012 | F37: 22751.921 | G37: 20219.984 | H37: 19652.225 | I37: 19670.499 | K37: 21511.552 | L37: 20219.984 | M37: 19652.225 | N37: 19670.499
B38: Mexico (2014) | C38: 2014 | D38: 2014 | F38: 23714.484 | G38: 20819.692 | H38: 19975.616 | I38: 20041.344 | K38: 22786.515 | L38: 20819.692 | M38: 19975.616 | N38: 20041.344
A39: =A36+1 -> 29 | B39: *,** Mongolia (2016) | C39: 2016 | D39: 2016
A40: =A39+1 -> 30 | B40: *,** Namibia (2009) | C40: 2009 | D40: 2009 -10
A41: =A40+1 -> 31 | B41: Nicaragua (2009) | C41: 2009 | D41: 2009
A42: =A41+1 -> 32 | B42: *,** Niger (2014) | C42: 2014 -15 | D42: 2014
...

Sheet 9.Poverty - Headcount ratio P05
A1: Go to Contents
B3: Poverty: Headcount ratio based international poverty lines in 2005 PPP $
B4: NOTE: FOR SOURCES AND CITATIONS SEE BOTTOM OF PAGE
B6: Country | C6: Year of survey | D6: Year of budgetary data and fiscal system | E6: Consumer price index 2005 | F6: Consumer price index 2011 | G6: Consumer price index year of survey | H6: PPP Conversion factor 2005 | I6: PPP Conversion factor 2011 | J6: Poverty line: $1.25 2005PPP/day converted to 2011PPP | K6: Poverty line: $2.5 2005PPP/day converted to 2011PPP | L6: Poverty line: $4 2005PPP/day converted to 2011PPP | N6: Poverty Headcount ratio
N7: Contributory pensions as deferred income | Z7: Contributory pensions as government transfer
N8: Poverty line: $1.25 2005PPP/day | R8: Poverty line: $2.5 2005PPP/day | V8: Poverty line: $4 2005PPP/day | Z8: Poverty line: $1.25 2005PPP/day | AD8: Poverty line: $2.5 2005PPP/day | AH8: Poverty line: $4 2005PPP/day
N9: Market income plus pensions | O9: Disposable income | P9: Consumable income | R9: Market income plus pensions | S9: Disposable income | T9: Consumable income | V9: Market income plus pensions | W9: Disposable income | X9: Consumable income | Z9: Market income | AA9: Disposable income | AB9: Consumable income | AD9: Market income | AE9: Disposable income | AF9: Consumable income | AH9: Market income | AI9: Disposable income | AJ9: Consumable income
A10: =A9+1 -> 1 | B10: *,** Albania (2015) | C10: 2015 | D10: 2015 | E10: 86.675568 | F10: 103.44284 | G10: 111.40497 | H10: 55.653665 | I10: 55.587503 | J10: 1.4935864 | K10: 2.9871728 | L10: 4.7794765 | R10: 0.07515 | S10: 0.048986 | T10: 0.081217 | V10: 0.225838 | W10: 0.212895 | X10: 0.291802 | AD10: 0.2304 | AE10: 0.048986 | AF10: 0.081217 | AI10: 0.212895 | AJ10: 0.291802
A11: =A10+1 -> 2 | B11: Argentina (2012) | C11: 2012-13 | D11: 2012 | G11: 110.61845 | H11: 1.3525982 | I11: 2.768382 | N11: 0.0131584 | O11: 0.0028047 | P11: 0.0045512 | R11: 0.0468899 | S11: 0.0182982 | T11: 0.0302906 | V11: 0.123191 | W11: 0.0727097 | X11: 0.1251874 | Z11: 0.0428835 | AA11: 0.0028047 | AB11: 0.0045512 | AD11: 0.0851461 | AE11: 0.0182982 | AF11: 0.0305623 | AH11: 0.1734772 | AI11: 0.0728372 | AJ11: 0.1252842
A12: =A11+1 -> 3 | B12: Armenia (2011) | C12: 2011 | D12: 2011 | E12: 76.379601 | F12: 107.65001 | G12: 107.65001 | H12: 196.18863 | I12: 183.7796 | J12: 1.8807161 | K12: 3.7614321 | L12: 6.0182914 | N12: 0.13102547 | O12: 0.098267843 | P12: 0.11864206 | R12: 0.31937487 | S12: 0.29684635 | T12: 0.35430746 | V12: 0.56016219 | W12: 0.56070078 | X12: 0.62793082 | Z12: 0.21348542 | AA12: 0.098267843 | AB12: 0.11864206 | AD12: 0.39585907 | AE12: 0.29684635 | AF12: 0.35430746 | AH12: 0.58762044 | AI12: 0.56070078 | AJ12: 0.62793082
A13: =A12+1 -> 4 | B13: *,** Belarus (2015) | C13: 2015 | D13: 2016 | H13: 759.62347 | I13: 0.18324348 | R13: 0.001775915 | V13: 0.0038691682 | Z13: 0.05884519 | AD13: 0.083035542 | AH13: 0.10584152
A14: =A13+1 -> 5 | B14: Bolivia (2009) | C14: 2009 | D14: 2009 | E14: 68.29517 | F14: 109.883 | G14: 97.559484 | H14: 2.5707953 | I14: 2.9061057 | J14: 1.402441 | K14: 2.804882 | L14: 4.4878111 | N14: 0.0996 | O14: 0.083523 | P14: 0.0973 | R14: 0.19604 | S14: 0.17573 | T14: 0.20245 | V14: 0.32488 | W14: 0.30656 | X14: 0.33926 | Z14: 0.10252 | AA14: 0.08352 | AB14: 0.09728 | AD14: 0.2001 | AE14: 0.1757 | AF14: 0.20246 | AH14: 0.33128 | AI14: 0.30656 | AJ14: 0.33926
A15: =A14+1 -> 6 | B15: Brazil (2008) | C15: 2008-09 | D15: 2009 | E15: 79.543671 | F15: 106.63637 | G15: 95.20298 | H15: 1.5713184 | I15: 1.6587826 | J15: 1.2652456 | K15: 2.5304912 | L15: 4.048786 | N15: 0.065500437 | O15: 0.041141782 | P15: 0.053183523 | R15: 0.17172535 | S15: 0.14412839 | T15: 0.17968315 | V15: 0.29488168 | W15: 0.27632963 | X15: 0.32923244 | Z15: 0.10492452 | AA15: 0.041141782 | AB15: 0.053183523 | AD15: 0.22994707 | AE15: 0.14412839 | AF15: 0.17968315 | AH15: 0.35929634 | AI15: 0.27632963 | AJ15: 0.32923244
