Workbook

Sheet Summary
L5: In UTA | P5: In CHL $ | V5: UTA values
D6: =+[1]tab!A1 -> year | E6: =+[1]tab!B1 -> tramo | F6: =+[1]tab!C1 -> tasa | G6: =+[1]tab!D1 -> N_GC | H6: =+[1]tab!E1 -> Y_GC | I6: =+[1]tab!F1 -> I_GC | J6: UTA | L6: Average income | M6: Average tax | N6: Average tax rate | P6: Average income | Q6: Average tax | R6: Average tax rate | V6: Year | W6: UTA
D7: =+[1]tab!A2 -> 2005 | E7: =+[1]tab!B2 -> 0 | F7: =+[1]tab!C2 -> 0 | G7: =+[1]tab!D2 -> 1187090 | H7: =+[1]tab!E2 -> 1841112.1 | I7: =+[1]tab!F2 -> 0.4 | J7: =+$W$7 -> 378852 | L7: =+H7/G7 -> 1.5509457 | M7: =+I7/G7 -> 3.3695844e-07 | N7: =+I7/H7 -> 2.1725999e-07 | P7: =+L7*J7 -> 587578.87 | Q7: =+M7*J7 -> 0.12765738 | R7: =+Q7/P7 -> 2.1725999e-07 | V7: 2005 | W7: =+[2]UTA!$B$14 -> 378852
D8: =+[1]tab!A3 -> 2005 | E8: =+[1]tab!B3 -> 13.5 | F8: =+[1]tab!C3 -> 0.05 | G8: =+[1]tab!D3 -> 322125 | H8: =+[1]tab!E3 -> 2472473.9 | I8: =+[1]tab!F3 -> 41215.6 | J8: =+$W$7 -> 378852 | L8: =+H8/G8 -> 7.6755107 | M8: =+I8/G8 -> 0.12794909 | N8: =+I8/H8 -> 0.016669782 | P8: =+L8*J8 -> 2907882.6 | Q8: =+M8*J8 -> 48473.768 | R8: =+Q8/P8 -> 0.016669782 | V8: 2006 | W8: =+[2]UTA!$B$13 -> 386472
D9: =+[1]tab!A4 -> 2005 | E9: =+[1]tab!B4 -> 30 | F9: =+[1]tab!C4 -> 0.1 | G9: =+[1]tab!D4 -> 142946 | H9: =+[1]tab!E4 -> 2083451.6 | I9: =+[1]tab!F4 -> 90505.7 | J9: =+$W$7 -> 378852 | L9: =+H9/G9 -> 14.575095 | M9: =+I9/G9 -> 0.63314608 | N9: =+I9/H9 -> 0.04344027 | P9: =+L9*J9 -> 5521804.1 | Q9: =+M9*J9 -> 239868.66 | R9: =+Q9/P9 -> 0.04344027 | V9: 2007 | W9: =+[2]UTA!$B$12 -> 410664
D10: =+[1]tab!A5 -> 2005 | E10: =+[1]tab!B5 -> 50 | F10: =+[1]tab!C5 -> 0.15 | G10: =+[1]tab!D5 -> 66633 | H10: =+[1]tab!E5 -> 1490430.4 | I10: =+[1]tab!F5 -> 105489.9 | J10: =+$W$7 -> 378852 | L10: =+H10/G10 -> 22.367752 | M10: =+I10/G10 -> 1.583148 | N10: =+I10/H10 -> 0.070778146 | P10: =+L10*J10 -> 8474067.5 | Q10: =+M10*J10 -> 599778.78 | R10: =+Q10/P10 -> 0.070778146 | V10: 2008 | W10: =+[2]UTA!$B$11 -> 451824
D11: =+[1]tab!A6 -> 2005 | E11: =+[1]tab!B6 -> 70 | F11: =+[1]tab!C6 -> 0.25 | G11: =+[1]tab!D6 -> 35706 | H11: =+[1]tab!E6 -> 1068038.5 | I11: =+[1]tab!F6 -> 108998 | J11: =+$W$7 -> 378852 | L11: =+H11/G11 -> 29.912018 | M11: =+I11/G11 -> 3.0526522 | N11: =+I11/H11 -> 0.10205437 | P11: =+L11*J11 -> 11332228 | Q11: =+M11*J11 -> 1156503.4 | R11: =+Q11/P11 -> 0.10205437 | V11: 2009 | W11: =+[2]UTA!$B$10 -> 442356
D12: =+[1]tab!A7 -> 2005 | E12: =+[1]tab!B7 -> 90 | F12: =+[1]tab!C7 -> 0.32 | G12: =+[1]tab!D7 -> 24220 | H12: =+[1]tab!E7 -> 942537.4 | I12: =+[1]tab!F7 -> 136587.4 | J12: =+$W$7 -> 378852 | L12: =+H12/G12 -> 38.915665 | M12: =+I12/G12 -> 5.6394467 | N12: =+I12/H12 -> 0.14491457 | P12: =+L12*J12 -> 14743277 | Q12: =+M12*J12 -> 2136515.7 | R12: =+Q12/P12 -> 0.14491457 | V12: 2010 | W12: =+[2]UTA!$B$9 -> 451260
D13: =+[1]tab!A8 -> 2005 | E13: =+[1]tab!B8 -> 120 | F13: =+[1]tab!C8 -> 0.37 | G13: =+[1]tab!D8 -> 9460 | H13: =+[1]tab!E8 -> 476080.1 | I13: =+[1]tab!F8 -> 90166.5 | J13: =+$W$7 -> 378852 | L13: =+H13/G13 -> 50.325592 | M13: =+I13/G13 -> 9.5313425 | N13: =+I13/H13 -> 0.18939355 | P13: =+L13*J13 -> 19065951 | Q13: =+M13*J13 -> 3610968.2 | R13: =+Q13/P13 -> 0.18939355 | V13: 2011 | W13: =+[2]UTA!$B$8 -> 468252
D14: =+[1]tab!A9 -> 2005 | E14: =+[1]tab!B9 -> 150 | F14: =+[1]tab!C9 -> 0.4 | G14: =+[1]tab!D9 -> 10505 | H14: =+[1]tab!E9 -> 1058296.2 | I14: =+[1]tab!F9 -> 309593.4 | J14: =+$W$7 -> 378852 | L14: =+H14/G14 -> 100.74214 | M14: =+I14/G14 -> 29.471052 | N14: =+I14/H14 -> 0.29253946 | P14: =+L14*J14 -> 38166362 | Q14: =+M14*J14 -> 11165167 | R14: =+Q14/P14 -> 0.29253946 | V14: 2012 | W14: =+[2]UTA!$B$7 -> 482472
D15: =+[1]tab!A10 -> 2006 | E15: =+[1]tab!B10 -> 0 | F15: =+[1]tab!C10 -> 0 | G15: =+[1]tab!D10 -> 1200653 | H15: =+[1]tab!E10 -> 1945336.2 | I15: =+[1]tab!F10 -> 3 | J15: =+$W$8 -> 386472 | L15: =+H15/G15 -> 1.6202318 | M15: =+I15/G15 -> 2.4986403e-06 | N15: =+I15/H15 -> 1.5421499e-06 | P15: =+L15*J15 -> 626174.23 | Q15: =+M15*J15 -> 0.96565452 | R15: =+Q15/P15 -> 1.5421499e-06 | V15: 2013 | W15: =+[2]UTA!$B$6 -> 489264
D16: =+[1]tab!A11 -> 2006 | E16: =+[1]tab!B11 -> 13.5 | F16: =+[1]tab!C11 -> 0.05 | G16: =+[1]tab!D11 -> 344808 | H16: =+[1]tab!E11 -> 2702640 | I16: =+[1]tab!F11 -> 45158.8 | J16: =+$W$8 -> 386472 | L16: =+H16/G16 -> 7.8381012 | M16: =+I16/G16 -> 0.13096796 | N16: =+I16/H16 -> 0.016709144 | P16: =+L16*J16 -> 3029206.6 | Q16: =+M16*J16 -> 50615.449 | R16: =+Q16/P16 -> 0.016709144 | V16: 2014 | W16: =+[2]UTA!$B$5 -> 518376
D17: =+[1]tab!A12 -> 2006 | E17: =+[1]tab!B12 -> 30 | F17: =+[1]tab!C12 -> 0.1 | G17: =+[1]tab!D12 -> 154107 | H17: =+[1]tab!E12 -> 2291386.3 | I17: =+[1]tab!F12 -> 99560.2 | J17: =+$W$8 -> 386472 | L17: =+H17/G17 -> 14.868801 | M17: =+I17/G17 -> 0.64604593 | N17: =+I17/H17 -> 0.043449767 | P17: =+L17*J17 -> 5746375.2 | Q17: =+M17*J17 -> 249678.66 | R17: =+Q17/P17 -> 0.043449767 | V17: 2015 | W17: =+[2]UTA!$B$4 -> 539460
D18: =+[1]tab!A13 -> 2006 | E18: =+[1]tab!B13 -> 50 | F18: =+[1]tab!C13 -> 0.15 | G18: =+[1]tab!D13 -> 72288 | H18: =+[1]tab!E13 -> 1653387.1 | I18: =+[1]tab!F13 -> 117339.3 | J18: =+$W$8 -> 386472 | L18: =+H18/G18 -> 22.872221 | M18: =+I18/G18 -> 1.6232196 | N18: =+I18/H18 -> 0.070969043 | P18: =+L18*J18 -> 8839472.9 | Q18: =+M18*J18 -> 627328.93 | R18: =+Q18/P18 -> 0.070969043 | V18: 2016 | W18: =+[2]UTA!$B$3 -> 554196
D19: =+[1]tab!A14 -> 2006 | E19: =+[1]tab!B14 -> 70 | F19: =+[1]tab!C14 -> 0.25 | G19: =+[1]tab!D14 -> 42329 | H19: =+[1]tab!E14 -> 1291867.2 | I19: =+[1]tab!F14 -> 131904.3 | J19: =+$W$8 -> 386472 | L19: =+H19/G19 -> 30.519672 | M19: =+I19/G19 -> 3.1161686 | N19: =+I19/H19 -> 0.10210361 | P19: =+L19*J19 -> 11794999 | Q19: =+M19*J19 -> 1204311.9 | R19: =+Q19/P19 -> 0.10210361 | V19: 2017 | W19: =+[2]UTA!$B$2 -> 563664
D20: =+[1]tab!A15 -> 2006 | E20: =+[1]tab!B15 -> 90 | F20: =+[1]tab!C15 -> 0.32 | G20: =+[1]tab!D15 -> 28036 | H20: =+[1]tab!E15 -> 1110409.3 | I20: =+[1]tab!F15 -> 160490.7 | J20: =+$W$8 -> 386472 | L20: =+H20/G20 -> 39.606552 | M20: =+I20/G20 -> 5.7244507 | N20: =+I20/H20 -> 0.14453292 | P20: =+L20*J20 -> 15306823 | Q20: =+M20*J20 -> 2212339.9 | R20: =+Q20/P20 -> 0.14453292 | V20: 2018 | W20: 580236
D21: =+[1]tab!A16 -> 2006 | E21: =+[1]tab!B16 -> 120 | F21: =+[1]tab!C16 -> 0.37 | G21: =+[1]tab!D16 -> 10735 | H21: =+[1]tab!E16 -> 551294.2 | I21: =+[1]tab!F16 -> 104413.7 | J21: =+$W$8 -> 386472 | L21: =+H21/G21 -> 51.354839 | M21: =+I21/G21 -> 9.7264741 | N21: =+I21/H21 -> 0.18939742 | P21: =+L21*J21 -> 19847207 | Q21: =+M21*J21 -> 3759009.9 | R21: =+Q21/P21 -> 0.18939742 | V21: 2019 | W21: 595476
D22: =+[1]tab!A17 -> 2006 | E22: =+[1]tab!B17 -> 150 | F22: =+[1]tab!C17 -> 0.4 | G22: =+[1]tab!D17 -> 11327 | H22: =+[1]tab!E17 -> 1164833.4 | I22: =+[1]tab!F17 -> 340196.9 | J22: =+$W$8 -> 386472 | L22: =+H22/G22 -> 102.83689 | M22: =+I22/G22 -> 30.034157 | N22: =+I22/H22 -> 0.29205627 | P22: =+L22*J22 -> 39743577 | Q22: =+M22*J22 -> 11607361 | R22: =+Q22/P22 -> 0.29205627 | V22: 2020 | W22: 612348
D23: =+[1]tab!A18 -> 2007 | E23: =+[1]tab!B18 -> 0 | F23: =+[1]tab!C18 -> 0 | G23: =+[1]tab!D18 -> 1186205 | H23: =+[1]tab!E18 -> 2099057.2 | I23: =+[1]tab!F18 -> 1.4 | J23: =+$W$9 -> 410664 | L23: =+H23/G23 -> 1.7695569 | M23: =+I23/G23 -> 1.1802344e-06 | N23: =+I23/H23 -> 6.669661e-07 | P23: =+L23*J23 -> 726693.3 | Q23: =+M23*J23 -> 0.4846798 | R23: =+Q23/P23 -> 6.669661e-07 | V23: 2021 | W23: 650052
D24: =+[1]tab!A19 -> 2007 | E24: =+[1]tab!B19 -> 13.5 | F24: =+[1]tab!C19 -> 0.05 | G24: =+[1]tab!D19 -> 366318 | H24: =+[1]tab!E19 -> 3053353 | I24: =+[1]tab!F19 -> 51096.8 | J24: =+$W$9 -> 410664 | L24: =+H24/G24 -> 8.3352524 | M24: =+I24/G24 -> 0.13948755 | N24: =+I24/H24 -> 0.016734652 | P24: =+L24*J24 -> 3422988.1 | Q24: =+M24*J24 -> 57282.515 | R24: =+Q24/P24 -> 0.016734652
D25: =+[1]tab!A20 -> 2007 | E25: =+[1]tab!B20 -> 30 | F25: =+[1]tab!C20 -> 0.1 | G25: =+[1]tab!D20 -> 165466 | H25: =+[1]tab!E20 -> 2622359.9 | I25: =+[1]tab!F20 -> 114390.8 | J25: =+$W$9 -> 410664 | L25: =+H25/G25 -> 15.848331 | M25: =+I25/G25 -> 0.69132511 | N25: =+I25/H25 -> 0.04362132 | P25: =+L25*J25 -> 6508338.9 | Q25: =+M25*J25 -> 283902.33 | R25: =+Q25/P25 -> 0.04362132
D26: =+[1]tab!A21 -> 2007 | E26: =+[1]tab!B21 -> 50 | F26: =+[1]tab!C21 -> 0.15 | G26: =+[1]tab!D21 -> 82676 | H26: =+[1]tab!E21 -> 2005960.1 | I26: =+[1]tab!F21 -> 142110.7 | J26: =+$W$9 -> 410664 | L26: =+H26/G26 -> 24.262907 | M26: =+I26/G26 -> 1.718887 | N26: =+I26/H26 -> 0.070844231 | P26: =+L26*J26 -> 9963902.4 | Q26: =+M26*J26 -> 705885 | R26: =+Q26/P26 -> 0.070844231
D27: =+[1]tab!A22 -> 2007 | E27: =+[1]tab!B22 -> 70 | F27: =+[1]tab!C22 -> 0.25 | G27: =+[1]tab!D22 -> 45180 | H27: =+[1]tab!E22 -> 1463426.2 | I27: =+[1]tab!F22 -> 149174.8 | J27: =+$W$9 -> 410664 | L27: =+H27/G27 -> 32.391018 | M27: =+I27/G27 -> 3.3017884 | N27: =+I27/H27 -> 0.10193531 | P27: =+L27*J27 -> 13301825 | Q27: =+M27*J27 -> 1355925.6 | R27: =+Q27/P27 -> 0.10193531
D28: =+[1]tab!A23 -> 2007 | E28: =+[1]tab!B23 -> 90 | F28: =+[1]tab!C23 -> 0.32 | G28: =+[1]tab!D23 -> 30173 | H28: =+[1]tab!E23 -> 1271988 | I28: =+[1]tab!F23 -> 184216.4 | J28: =+$W$9 -> 410664 | L28: =+H28/G28 -> 42.156498 | M28: =+I28/G28 -> 6.1053392 | N28: =+I28/H28 -> 0.14482558 | P28: =+L28*J28 -> 17312156 | Q28: =+M28*J28 -> 2507243 | R28: =+Q28/P28 -> 0.14482558
D29: =+[1]tab!A24 -> 2007 | E29: =+[1]tab!B24 -> 120 | F29: =+[1]tab!C24 -> 0.37 | G29: =+[1]tab!D24 -> 11829 | H29: =+[1]tab!E24 -> 646778.5 | I29: =+[1]tab!F24 -> 122798.2 | J29: =+$W$9 -> 410664 | L29: =+H29/G29 -> 54.677361 | M29: =+I29/G29 -> 10.381114 | N29: =+I29/H29 -> 0.18986129 | P29: =+L29*J29 -> 22454024 | Q29: =+M29*J29 -> 4263149.9 | R29: =+Q29/P29 -> 0.18986129
D30: =+[1]tab!A25 -> 2007 | E30: =+[1]tab!B25 -> 150 | F30: =+[1]tab!C25 -> 0.4 | G30: =+[1]tab!D25 -> 12484 | H30: =+[1]tab!E25 -> 1349216.6 | I30: =+[1]tab!F25 -> 393313.8 | J30: =+$W$9 -> 410664 | L30: =+H30/G30 -> 108.07566 | M30: =+I30/G30 -> 31.505431 | N30: =+I30/H30 -> 0.29151272 | P30: =+L30*J30 -> 44382785 | Q30: =+M30*J30 -> 12938146 | R30: =+Q30/P30 -> 0.29151272
D31: =+[1]tab!A26 -> 2008 | E31: =+[1]tab!B26 -> 0 | F31: =+[1]tab!C26 -> 0 | G31: =+[1]tab!D26 -> 1207673 | H31: =+[1]tab!E26 -> 2394070.7 | I31: =+[1]tab!F26 -> 0.8 | J31: =+$W$10 -> 451824 | L31: =+H31/G31 -> 1.9823832 | M31: =+I31/G31 -> 6.6243097e-07 | N31: =+I31/H31 -> 3.3415889e-07 | P31: =+L31*J31 -> 895688.32 | Q31: =+M31*J31 -> 0.29930221 | R31: =+Q31/P31 -> 3.3415889e-07
D32: =+[1]tab!A27 -> 2008 | E32: =+[1]tab!B27 -> 13.5 | F32: =+[1]tab!C27 -> 0.05 | G32: =+[1]tab!D27 -> 387722 | H32: =+[1]tab!E27 -> 3549449.3 | I32: =+[1]tab!F27 -> 59183.3 | J32: =+$W$10 -> 451824 | L32: =+H32/G32 -> 9.1546244 | M32: =+I32/G32 -> 0.15264365 | N32: =+I32/H32 -> 0.016673939 | P32: =+L32*J32 -> 4136279 | Q32: =+M32*J32 -> 68968.063 | R32: =+Q32/P32 -> 0.016673939
D33: =+[1]tab!A28 -> 2008 | E33: =+[1]tab!B28 -> 30 | F33: =+[1]tab!C28 -> 0.1 | G33: =+[1]tab!D28 -> 174711 | H33: =+[1]tab!E28 -> 3044761.2 | I33: =+[1]tab!F28 -> 132699.3 | J33: =+$W$10 -> 451824 | L33: =+H33/G33 -> 17.427416 | M33: =+I33/G33 -> 0.75953603 | N33: =+I33/H33 -> 0.043582827 | P33: =+L33*J33 -> 7874124.6 | Q33: =+M33*J33 -> 343176.61 | R33: =+Q33/P33 -> 0.043582827
D34: =+[1]tab!A29 -> 2008 | E34: =+[1]tab!B29 -> 50 | F34: =+[1]tab!C29 -> 0.15 | G34: =+[1]tab!D29 -> 85624 | H34: =+[1]tab!E29 -> 2281341 | I34: =+[1]tab!F29 -> 161242.7 | J34: =+$W$10 -> 451824 | L34: =+H34/G34 -> 26.64371 | M34: =+I34/G34 -> 1.8831484 | N34: =+I34/H34 -> 0.070678912 | P34: =+L34*J34 -> 12038267 | Q34: =+M34*J34 -> 850851.65 | R34: =+Q34/P34 -> 0.070678912
D35: =+[1]tab!A30 -> 2008 | E35: =+[1]tab!B30 -> 70 | F35: =+[1]tab!C30 -> 0.25 | G35: =+[1]tab!D30 -> 43775 | H35: =+[1]tab!E30 -> 1559043.7 | I35: =+[1]tab!F30 -> 158704.1 | J35: =+$W$10 -> 451824 | L35: =+H35/G35 -> 35.614933 | M35: =+I35/G35 -> 3.6254506 | N35: =+I35/H35 -> 0.1017958 | P35: =+L35*J35 -> 16091682 | Q35: =+M35*J35 -> 1638065.6 | R35: =+Q35/P35 -> 0.1017958
D36: =+[1]tab!A31 -> 2008 | E36: =+[1]tab!B31 -> 90 | F36: =+[1]tab!C31 -> 0.32 | G36: =+[1]tab!D31 -> 30125 | H36: =+[1]tab!E31 -> 1396254.1 | I36: =+[1]tab!F31 -> 201975.9 | J36: =+$W$10 -> 451824 | L36: =+H36/G36 -> 46.348684 | M36: =+I36/G36 -> 6.7045942 | N36: =+I36/H36 -> 0.14465555 | P36: =+L36*J36 -> 20941448 | Q36: =+M36*J36 -> 3029296.6 | R36: =+Q36/P36 -> 0.14465555
D37: =+[1]tab!A32 -> 2008 | E37: =+[1]tab!B32 -> 120 | F37: =+[1]tab!C32 -> 0.37 | G37: =+[1]tab!D32 -> 11964 | H37: =+[1]tab!E32 -> 718803.4 | I37: =+[1]tab!F32 -> 136230.8 | J37: =+$W$10 -> 451824 | L37: =+H37/G37 -> 60.080525 | M37: =+I37/G37 -> 11.386727 | N37: =+I37/H37 -> 0.18952442 | P37: =+L37*J37 -> 27145823 | Q37: =+M37*J37 -> 5144796.5 | R37: =+Q37/P37 -> 0.18952442
D38: =+[1]tab!A33 -> 2008 | E38: =+[1]tab!B33 -> 150 | F38: =+[1]tab!C33 -> 0.4 | G38: =+[1]tab!D33 -> 12601 | H38: =+[1]tab!E33 -> 1525739.2 | I38: =+[1]tab!F33 -> 447708.8 | J38: =+$W$10 -> 451824 | L38: =+H38/G38 -> 121.0808 | M38: =+I38/G38 -> 35.529625 | N38: =+I38/H38 -> 0.29343731 | P38: =+L38*J38 -> 54707213 | Q38: =+M38*J38 -> 16053137 | R38: =+Q38/P38 -> 0.29343731
D39: =+[1]tab!A34 -> 2009 | E39: =+[1]tab!B34 -> 0 | F39: =+[1]tab!C34 -> 0 | G39: =+[1]tab!D34 -> 1211558 | H39: =+[1]tab!E34 -> 2346371.3 | I39: =+[1]tab!F34 -> 2.2 | J39: =+$W$11 -> 442356 | L39: =+H39/G39 -> 1.9366562 | M39: =+I39/G39 -> 1.8158437e-06 | N39: =+I39/H39 -> 9.3761801e-07 | P39: =+L39*J39 -> 856691.49 | Q39: =+M39*J39 -> 0.80324937 | R39: =+Q39/P39 -> 9.3761801e-07
D40: =+[1]tab!A35 -> 2009 | E40: =+[1]tab!B35 -> 13.5 | F40: =+[1]tab!C35 -> 0.05 | G40: =+[1]tab!D35 -> 398336 | H40: =+[1]tab!E35 -> 3578437.4 | I40: =+[1]tab!F35 -> 59943.4 | J40: =+$W$11 -> 442356 | L40: =+H40/G40 -> 8.9834647 | M40: =+I40/G40 -> 0.15048452 | N40: =+I40/H40 -> 0.016751278 | P40: =+L40*J40 -> 3973889.5 | Q40: =+M40*J40 -> 66567.728 | R40: =+Q40/P40 -> 0.016751278
D41: =+[1]tab!A36 -> 2009 | E41: =+[1]tab!B36 -> 30 | F41: =+[1]tab!C36 -> 0.1 | G41: =+[1]tab!D36 -> 181589 | H41: =+[1]tab!E36 -> 3099099.3 | I41: =+[1]tab!F36 -> 135112.1 | J41: =+$W$11 -> 442356 | L41: =+H41/G41 -> 17.066559 | M41: =+I41/G41 -> 0.74405443 | N41: =+I41/H41 -> 0.043597215 | P41: =+L41*J41 -> 7549494.6 | Q41: =+M41*J41 -> 329136.94 | R41: =+Q41/P41 -> 0.043597215
D42: =+[1]tab!A37 -> 2009 | E42: =+[1]tab!B37 -> 50 | F42: =+[1]tab!C37 -> 0.15 | G42: =+[1]tab!D37 -> 88434 | H42: =+[1]tab!E37 -> 2311690.2 | I42: =+[1]tab!F37 -> 163779.9 | J42: =+$W$11 -> 442356 | L42: =+H42/G42 -> 26.140288 | M42: =+I42/G42 -> 1.8520015 | N42: =+I42/H42 -> 0.070848551 | P42: =+L42*J42 -> 11563313 | Q42: =+M42*J42 -> 819243.97 | R42: =+Q42/P42 -> 0.070848551
D43: =+[1]tab!A38 -> 2009 | E43: =+[1]tab!B38 -> 70 | F43: =+[1]tab!C38 -> 0.25 | G43: =+[1]tab!D38 -> 50186 | H43: =+[1]tab!E38 -> 1753662.7 | I43: =+[1]tab!F38 -> 179108.6 | J43: =+$W$11 -> 442356 | L43: =+H43/G43 -> 34.943265 | M43: =+I43/G43 -> 3.5688957 | N43: =+I43/H43 -> 0.10213401 | P43: =+L43*J43 -> 15457363 | Q43: =+M43*J43 -> 1578722.4 | R43: =+Q43/P43 -> 0.10213401
D44: =+[1]tab!A39 -> 2009 | E44: =+[1]tab!B39 -> 90 | F44: =+[1]tab!C39 -> 0.32 | G44: =+[1]tab!D39 -> 35686 | H44: =+[1]tab!E39 -> 1619432.2 | I44: =+[1]tab!F39 -> 234284.3 | J44: =+$W$11 -> 442356 | L44: =+H44/G44 -> 45.380043 | M44: =+I44/G44 -> 6.56516 | N44: =+I44/H44 -> 0.14467064 | P44: =+L44*J44 -> 20074134 | Q44: =+M44*J44 -> 2904137.9 | R44: =+Q44/P44 -> 0.14467064
...

Sheet 2005
B2: =+Summary!P6 -> Average income | C2: =+Summary!Q6 -> Average tax | D2: =+Summary!R6 -> Average tax rate
B3: =+Summary!P7 -> 587578.87 | C3: =+Summary!Q7 -> 0.12765738 | D3: =+Summary!R7 -> 2.1725999e-07
B4: =+Summary!P8 -> 2907882.6 | C4: =+Summary!Q8 -> 48473.768 | D4: =+Summary!R8 -> 0.016669782
B5: =+Summary!P9 -> 5521804.1 | C5: =+Summary!Q9 -> 239868.66 | D5: =+Summary!R9 -> 0.04344027
B6: =+Summary!P10 -> 8474067.5 | C6: =+Summary!Q10 -> 599778.78 | D6: =+Summary!R10 -> 0.070778146
B7: =+Summary!P11 -> 11332228 | C7: =+Summary!Q11 -> 1156503.4 | D7: =+Summary!R11 -> 0.10205437
B8: =+Summary!P12 -> 14743277 | C8: =+Summary!Q12 -> 2136515.7 | D8: =+Summary!R12 -> 0.14491457
B9: =+Summary!P13 -> 19065951 | C9: =+Summary!Q13 -> 3610968.2 | D9: =+Summary!R13 -> 0.18939355
B10: =+Summary!P14 -> 38166362 | C10: =+Summary!Q14 -> 11165167 | D10: =+Summary!R14 -> 0.29253946

Sheet 2006
B2: =+Summary!P6 -> Average income | C2: =+Summary!Q6 -> Average tax | D2: =+Summary!R6 -> Average tax rate
B3: =+Summary!P15 -> 626174.23 | C3: =+Summary!Q15 -> 0.96565452 | D3: =+Summary!R15 -> 1.5421499e-06
B4: =+Summary!P16 -> 3029206.6 | C4: =+Summary!Q16 -> 50615.449 | D4: =+Summary!R16 -> 0.016709144
B5: =+Summary!P17 -> 5746375.2 | C5: =+Summary!Q17 -> 249678.66 | D5: =+Summary!R17 -> 0.043449767
B6: =+Summary!P18 -> 8839472.9 | C6: =+Summary!Q18 -> 627328.93 | D6: =+Summary!R18 -> 0.070969043
B7: =+Summary!P19 -> 11794999 | C7: =+Summary!Q19 -> 1204311.9 | D7: =+Summary!R19 -> 0.10210361
B8: =+Summary!P20 -> 15306823 | C8: =+Summary!Q20 -> 2212339.9 | D8: =+Summary!R20 -> 0.14453292
B9: =+Summary!P21 -> 19847207 | C9: =+Summary!Q21 -> 3759009.9 | D9: =+Summary!R21 -> 0.18939742
B10: =+Summary!P22 -> 39743577 | C10: =+Summary!Q22 -> 11607361 | D10: =+Summary!R22 -> 0.29205627

Sheet 2007
B2: =+Summary!P6 -> Average income | C2: =+Summary!Q6 -> Average tax | D2: =+Summary!R6 -> Average tax rate
B3: =+Summary!P23 -> 726693.3 | C3: =+Summary!Q23 -> 0.4846798 | D3: =+Summary!R23 -> 6.669661e-07
B4: =+Summary!P24 -> 3422988.1 | C4: =+Summary!Q24 -> 57282.515 | D4: =+Summary!R24 -> 0.016734652
B5: =+Summary!P25 -> 6508338.9 | C5: =+Summary!Q25 -> 283902.33 | D5: =+Summary!R25 -> 0.04362132
B6: =+Summary!P26 -> 9963902.4 | C6: =+Summary!Q26 -> 705885 | D6: =+Summary!R26 -> 0.070844231
B7: =+Summary!P27 -> 13301825 | C7: =+Summary!Q27 -> 1355925.6 | D7: =+Summary!R27 -> 0.10193531
B8: =+Summary!P28 -> 17312156 | C8: =+Summary!Q28 -> 2507243 | D8: =+Summary!R28 -> 0.14482558
B9: =+Summary!P29 -> 22454024 | C9: =+Summary!Q29 -> 4263149.9 | D9: =+Summary!R29 -> 0.18986129
B10: =+Summary!P30 -> 44382785 | C10: =+Summary!Q30 -> 12938146 | D10: =+Summary!R30 -> 0.29151272

Sheet 2008
B2: =+Summary!P6 -> Average income | C2: =+Summary!Q6 -> Average tax | D2: =+Summary!R6 -> Average tax rate
B3: =+Summary!P31 -> 895688.32 | C3: =+Summary!Q31 -> 0.29930221 | D3: =+Summary!R31 -> 3.3415889e-07
B4: =+Summary!P32 -> 4136279 | C4: =+Summary!Q32 -> 68968.063 | D4: =+Summary!R32 -> 0.016673939
B5: =+Summary!P33 -> 7874124.6 | C5: =+Summary!Q33 -> 343176.61 | D5: =+Summary!R33 -> 0.043582827
B6: =+Summary!P34 -> 12038267 | C6: =+Summary!Q34 -> 850851.65 | D6: =+Summary!R34 -> 0.070678912
B7: =+Summary!P35 -> 16091682 | C7: =+Summary!Q35 -> 1638065.6 | D7: =+Summary!R35 -> 0.1017958
B8: =+Summary!P36 -> 20941448 | C8: =+Summary!Q36 -> 3029296.6 | D8: =+Summary!R36 -> 0.14465555
B9: =+Summary!P37 -> 27145823 | C9: =+Summary!Q37 -> 5144796.5 | D9: =+Summary!R37 -> 0.18952442
B10: =+Summary!P38 -> 54707213 | C10: =+Summary!Q38 -> 16053137 | D10: =+Summary!R38 -> 0.29343731

Sheet 2009
B2: =+Summary!P6 -> Average income | C2: =+Summary!Q6 -> Average tax | D2: =+Summary!R6 -> Average tax rate
B3: =+Summary!P39 -> 856691.49 | C3: =+Summary!Q39 -> 0.80324937 | D3: =+Summary!R39 -> 9.3761801e-07
B4: =+Summary!P40 -> 3973889.5 | C4: =+Summary!Q40 -> 66567.728 | D4: =+Summary!R40 -> 0.016751278
B5: =+Summary!P41 -> 7549494.6 | C5: =+Summary!Q41 -> 329136.94 | D5: =+Summary!R41 -> 0.043597215
B6: =+Summary!P42 -> 11563313 | C6: =+Summary!Q42 -> 819243.97 | D6: =+Summary!R42 -> 0.070848551
B7: =+Summary!P43 -> 15457363 | C7: =+Summary!Q43 -> 1578722.4 | D7: =+Summary!R43 -> 0.10213401
B8: =+Summary!P44 -> 20074134 | C8: =+Summary!Q44 -> 2904137.9 | D8: =+Summary!R44 -> 0.14467064
B9: =+Summary!P45 -> 25974937 | C9: =+Summary!Q45 -> 4916570.1 | D9: =+Summary!R45 -> 0.18928131
B10: =+Summary!P46 -> 50560187 | C10: =+Summary!Q46 -> 14641307 | D10: =+Summary!R46 -> 0.28958175

Sheet 2010
B2: =+Summary!P6 -> Average income | C2: =+Summary!Q6 -> Average tax | D2: =+Summary!R6 -> Average tax rate
B3: =+Summary!P47 -> 908234 | C3: =+Summary!Q47 -> 0.14632058 | D3: =+Summary!R47 -> 1.611045e-07
B4: =+Summary!P48 -> 4152906.9 | C4: =+Summary!Q48 -> 70134.241 | D4: =+Summary!R48 -> 0.016887988
B5: =+Summary!P49 -> 7863404.2 | C5: =+Summary!Q49 -> 343206.63 | D5: =+Summary!R49 -> 0.043646063
B6: =+Summary!P50 -> 12037986 | C6: =+Summary!Q50 -> 853016.24 | D6: =+Summary!R50 -> 0.070860377
B7: =+Summary!P51 -> 16108444 | C7: =+Summary!Q51 -> 1648253.7 | D7: =+Summary!R51 -> 0.10232234
B8: =+Summary!P52 -> 20932104 | C8: =+Summary!Q52 -> 3035513.7 | D8: =+Summary!R52 -> 0.14501713
B9: =+Summary!P53 -> 27024843 | C9: =+Summary!Q53 -> 5112477.7 | D9: =+Summary!R53 -> 0.18917696
B10: =+Summary!P54 -> 52673462 | C10: =+Summary!Q54 -> 15252425 | D10: =+Summary!R54 -> 0.28956565

Sheet 2011
B2: =+Summary!P6 -> Average income | C2: =+Summary!Q6 -> Average tax | D2: =+Summary!R6 -> Average tax rate
B3: =+Summary!P55 -> 1001727.6 | C3: =+Summary!Q55 -> 1.0010479 | D3: =+Summary!R55 -> 9.9932139e-07
B4: =+Summary!P56 -> 4474186.5 | C4: =+Summary!Q56 -> 75654.492 | D4: =+Summary!R56 -> 0.016909105
B5: =+Summary!P57 -> 8449188.5 | C5: =+Summary!Q57 -> 367726.04 | D5: =+Summary!R57 -> 0.043522054
B6: =+Summary!P58 -> 12969621 | C6: =+Summary!Q58 -> 919631.32 | D6: =+Summary!R58 -> 0.070906569
B7: =+Summary!P59 -> 17318983 | C7: =+Summary!Q59 -> 1768645.5 | D7: =+Summary!R59 -> 0.10212178
B8: =+Summary!P60 -> 22535983 | C8: =+Summary!Q60 -> 3267627.8 | D8: =+Summary!R60 -> 0.14499602
B9: =+Summary!P61 -> 29149851 | C9: =+Summary!Q61 -> 5523850 | D9: =+Summary!R61 -> 0.1894984
B10: =+Summary!P62 -> 58260144 | C10: =+Summary!Q62 -> 17049347 | D10: =+Summary!R62 -> 0.2926417

Sheet 2012
B2: =+Summary!P6 -> Average income | C2: =+Summary!Q6 -> Average tax | D2: =+Summary!R6 -> Average tax rate
B3: =+Summary!P63 -> 1240954 | C3: =+Summary!Q63 -> 0.64777405 | D3: =+Summary!R63 -> 5.2199684e-07
B4: =+Summary!P64 -> 4656701.8 | C4: =+Summary!Q64 -> 75639.951 | D4: =+Summary!R64 -> 0.016243246
B5: =+Summary!P65 -> 8929201.2 | C5: =+Summary!Q65 -> 386274.64 | D5: =+Summary!R65 -> 0.043259708
B6: =+Summary!P66 -> 13725087 | C6: =+Summary!Q66 -> 969623.63 | D6: =+Summary!R66 -> 0.070646083
B7: =+Summary!P67 -> 18389232 | C7: =+Summary!Q67 -> 1877932 | D7: =+Summary!R67 -> 0.10212128
B8: =+Summary!P68 -> 24007155 | C8: =+Summary!Q68 -> 3495303.8 | D8: =+Summary!R68 -> 0.14559425
B9: =+Summary!P69 -> 30880215 | C9: =+Summary!Q69 -> 5840363.1 | D9: =+Summary!R69 -> 0.18912961
B10: =+Summary!P70 -> 59440934 | C10: =+Summary!Q70 -> 17119701 | D10: =+Summary!R70 -> 0.28801198

Sheet 2013
B2: =+Summary!P6 -> Average income | C2: =+Summary!Q6 -> Average tax | D2: =+Summary!R6 -> Average tax rate
B3: =+Summary!P71 -> 1318936.8 | C3: =+Summary!Q71 -> 1.0157369 | D3: =+Summary!R71 -> 7.7011792e-07
B4: =+Summary!P72 -> 4796302.3 | C4: =+Summary!Q72 -> 62538.131 | D4: =+Summary!R72 -> 0.013038822
B5: =+Summary!P73 -> 9177399.3 | C5: =+Summary!Q73 -> 317389.49 | D5: =+Summary!R73 -> 0.034583816
B6: =+Summary!P74 -> 14123971 | C6: =+Summary!Q74 -> 831151.93 | D6: =+Summary!R74 -> 0.058846901
B7: =+Summary!P75 -> 18901928 | C7: =+Summary!Q75 -> 1679160.2 | D7: =+Summary!R75 -> 0.088835393
B8: =+Summary!P76 -> 24651484 | C8: =+Summary!Q76 -> 3230418.3 | D8: =+Summary!R76 -> 0.13104356
B9: =+Summary!P77 -> 31792285 | C9: =+Summary!Q77 -> 5555077.8 | D9: =+Summary!R77 -> 0.17473037
B10: =+Summary!P78 -> 61154896 | C10: =+Summary!Q78 -> 17104863 | D10: =+Summary!R78 -> 0.27969737

Sheet 2014
B2: =+Summary!P6 -> Average income | C2: =+Summary!Q6 -> Average tax | D2: =+Summary!R6 -> Average tax rate
B3: =+Summary!P79 -> 1514888 | C3: =+Summary!Q79 -> 0.88544495 | D3: =+Summary!R79 -> 5.8449531e-07
B4: =+Summary!P80 -> 5373403.4 | C4: =+Summary!Q80 -> 69792.863 | D4: =+Summary!R80 -> 0.012988577
B5: =+Summary!P81 -> 10290713 | C5: =+Summary!Q81 -> 355540.39 | D5: =+Summary!R81 -> 0.034549637
B6: =+Summary!P82 -> 15855871 | C6: =+Summary!Q82 -> 933665.66 | D6: =+Summary!R82 -> 0.058884538
B7: =+Summary!P83 -> 21219581 | C7: =+Summary!Q83 -> 1886107.1 | D7: =+Summary!R83 -> 0.088885215
B8: =+Summary!P84 -> 27682660 | C8: =+Summary!Q84 -> 3630900.1 | D8: =+Summary!R84 -> 0.13116153
B9: =+Summary!P85 -> 35755932 | C9: =+Summary!Q85 -> 6263147.1 | D9: =+Summary!R85 -> 0.17516386
B10: =+Summary!P86 -> 69005966 | C10: =+Summary!Q86 -> 19350389 | D10: =+Summary!R86 -> 0.28041617

Sheet 2015
B2: =+Summary!P6 -> Average income | C2: =+Summary!Q6 -> Average tax | D2: =+Summary!R6 -> Average tax rate
B3: =+Summary!P87 -> 1630677.4 | C3: =+Summary!Q87 -> 1.1841909 | D3: =+Summary!R87 -> 7.2619568e-07
B4: =+Summary!P88 -> 5812672.7 | C4: =+Summary!Q88 -> 75323.837 | D4: =+Summary!R88 -> 0.012958555
B5: =+Summary!P89 -> 11132343 | C5: =+Summary!Q89 -> 384079.5 | D5: =+Summary!R89 -> 0.034501227
B6: =+Summary!P90 -> 17159939 | C6: =+Summary!Q90 -> 1009586 | D6: =+Summary!R90 -> 0.05883389
B7: =+Summary!P91 -> 22958500 | C7: =+Summary!Q91 -> 2037618.3 | D7: =+Summary!R91 -> 0.088752241
B8: =+Summary!P92 -> 30024341 | C8: =+Summary!Q92 -> 3945703.9 | D8: =+Summary!R92 -> 0.13141684
B9: =+Summary!P93 -> 38754124 | C9: =+Summary!Q93 -> 6794393.3 | D9: =+Summary!R93 -> 0.17532053
B10: =+Summary!P94 -> 76762853 | C10: =+Summary!Q94 -> 21772845 | D10: =+Summary!R94 -> 0.28363778

Sheet 2016
B2: =+Summary!P6 -> Average income | C2: =+Summary!Q6 -> Average tax | D2: =+Summary!R6 -> Average tax rate
B3: =+Summary!P95 -> 1713761.4 | C3: =+Summary!Q95 -> 0 | D3: =+Summary!R95 -> 0
B4: =+Summary!P96 -> 6133424.1 | C4: =+Summary!Q96 -> 79451.942 | D4: =+Summary!R96 -> 0.012953929
B5: =+Summary!P97 -> 11752112 | C5: =+Summary!Q97 -> 405636.52 | D5: =+Summary!R97 -> 0.034516053
B6: =+Summary!P98 -> 18104783 | C6: =+Summary!Q98 -> 1064786.2 | D6: =+Summary!R98 -> 0.058812422
B7: =+Summary!P99 -> 24272721 | C7: =+Summary!Q99 -> 2160342.1 | D7: =+Summary!R99 -> 0.089002879
B8: =+Summary!P100 -> 31691612 | C8: =+Summary!Q100 -> 4166023.5 | D8: =+Summary!R100 -> 0.13145508
B9: =+Summary!P101 -> 40906491 | C9: =+Summary!Q101 -> 7171959 | D9: =+Summary!R101 -> 0.17532569
B10: =+Summary!P102 -> 79896921 | C10: =+Summary!Q102 -> 22496109 | D10: =+Summary!R102 -> 0.28156415

Sheet 2017
B2: =+Summary!P6 -> Average income | C2: =+Summary!Q6 -> Average tax | D2: =+Summary!R6 -> Average tax rate
B3: =+Summary!P103 -> 1743754.7 | C3: =+Summary!Q103 -> 0.73738229 | D3: =+Summary!R103 -> 4.2287041e-07
B4: =+Summary!P104 -> 6364742.7 | C4: =+Summary!Q104 -> 82992.458 | D4: =+Summary!R104 -> 0.013039405
B5: =+Summary!P105 -> 12146820 | C5: =+Summary!Q105 -> 418805.96 | D5: =+Summary!R105 -> 0.03447865
B6: =+Summary!P106 -> 18689797 | C6: =+Summary!Q106 -> 1096231.6 | D6: =+Summary!R106 -> 0.058654011
B7: =+Summary!P107 -> 25093858 | C7: =+Summary!Q107 -> 2231608.5 | D7: =+Summary!R107 -> 0.088930465
B8: =+Summary!P108 -> 32803146 | C8: =+Summary!Q108 -> 4315261.2 | D8: =+Summary!R108 -> 0.13155022
B9: =+Summary!P109 -> 71829741 | C9: =+Summary!Q109 -> 17723526 | D9: =+Summary!R109 -> 0.24674356
B10: =+Summary!P110 -> 1869700.8 | C10: =+Summary!Q110 -> 0.033724495 | D10: =+Summary!R110 -> 1.8037375e-08

Sheet 2018
B2: =+Summary!P6 -> Average income | C2: =+Summary!Q6 -> Average tax | D2: =+Summary!R6 -> Average tax rate
B3: =+Summary!P110 -> 1869700.8 | C3: =+Summary!Q110 -> 0.033724495 | D3: =+Summary!R110 -> 1.8037375e-08
B4: =+Summary!P111 -> 6761441.6 | C4: =+Summary!Q111 -> 88625.157 | D4: =+Summary!R111 -> 0.013107435
B5: =+Summary!P112 -> 12853646 | C5: =+Summary!Q112 -> 442361.85 | D5: =+Summary!R112 -> 0.034415281
B6: =+Summary!P113 -> 19808907 | C6: =+Summary!Q113 -> 1162207.8 | D6: =+Summary!R113 -> 0.058670967
B7: =+Summary!P114 -> 26578759 | C7: =+Summary!Q114 -> 2361811.9 | D7: =+Summary!R114 -> 0.088860878
B8: =+Summary!P115 -> 34737995 | C8: =+Summary!Q115 -> 4565973.3 | D8: =+Summary!R115 -> 0.13144032
B9: =+Summary!P116 -> 76750561 | C9: =+Summary!Q116 -> 19004766 | D9: =+Summary!R116 -> 0.2476173
B10: =+Summary!P117 -> 1970488.2 | C10: =+Summary!Q117 -> 0.10098736 | D10: =+Summary!R117 -> 5.1249919e-08

Sheet 2019
B2: =+Summary!P6 -> Average income | C2: =+Summary!Q6 -> Average tax | D2: =+Summary!R6 -> Average tax rate
B3: =+Summary!P117 -> 1970488.2 | C3: =+Summary!Q117 -> 0.10098736 | D3: =+Summary!R117 -> 5.1249919e-08
B4: =+Summary!P118 -> 7124708.7 | C4: =+Summary!Q118 -> 93476.6 | D4: =+Summary!R118 -> 0.013120059
B5: =+Summary!P119 -> 13541317 | C5: =+Summary!Q119 -> 466197.05 | D5: =+Summary!R119 -> 0.034427749
B6: =+Summary!P120 -> 20853806 | C6: =+Summary!Q120 -> 1222832.9 | D6: =+Summary!R120 -> 0.058638358
B7: =+Summary!P121 -> 27990821 | C7: =+Summary!Q121 -> 2486968.6 | D7: =+Summary!R121 -> 0.088849434
B8: =+Summary!P122 -> 36572278 | C8: =+Summary!Q122 -> 4804436.4 | D8: =+Summary!R122 -> 0.13136826
B9: =+Summary!P123 -> 84550918 | C9: =+Summary!Q123 -> 21320781 | D9: =+Summary!R123 -> 0.25216498
B10: =+Summary!P124 -> 2084837.7 | C10: =+Summary!Q124 -> 0 | D10: =+Summary!R124 -> 0

Sheet 2020
B2: =+Summary!P6 -> Average income | C2: =+Summary!Q6 -> Average tax | D2: =+Summary!R6 -> Average tax rate
B3: =+Summary!P124 -> 2084837.7 | C3: =+Summary!Q124 -> 0 | D3: =+Summary!R124 -> 0
B4: =+Summary!P125 -> 7545319.9 | C4: =+Summary!Q125 -> 99272.94 | D4: =+Summary!R125 -> 0.013156889
B5: =+Summary!P126 -> 14581997 | C5: =+Summary!Q126 -> 513896.35 | D5: =+Summary!R126 -> 0.035241837
B6: =+Summary!P127 -> 22015217 | C6: =+Summary!Q127 -> 1287900.7 | D6: =+Summary!R127 -> 0.058500477
B7: =+Summary!P128 -> 29541910 | C7: =+Summary!Q128 -> 2615848.5 | D7: =+Summary!R128 -> 0.088547035
B8: =+Summary!P129 -> 38629178 | C8: =+Summary!Q129 -> 5066106.4 | D8: =+Summary!R129 -> 0.13114715
B9: =+Summary!P130 -> 63294677 | C9: =+Summary!Q130 -> 13401555 | D9: =+Summary!R130 -> 0.21173273
B10: =+Summary!P131 -> 2.1730447e+08 | C10: =+Summary!Q131 -> 72229859 | D10: =+Summary!R131 -> 0.33239011
B11: =+Summary!P132 -> 2406438.5 | C11: =+Summary!Q132 -> 0 | D11: =+Summary!R132 -> 0
